Workbook

Sheet หน้าหลัก
A1: รายงานการใช้จ่ายเงินงบประมาณรายได้ ประจำปีงบประมาณ พ.ศ. 2569
A2: ชื่อหน่วยงาน คณะศิลปศาสตร์และวิทยาศาสตร์
A3: รายจ่ายจำแนกตามโครงการงบประมาณรายได้ จำนวน 9 โครงการ
A4: ที่ | B4: หน่วยงาน | C4: ขออนุมัติ | D4: ดำเนินการ | E4: คงเหลือ | F4: เปอร์เซ็น
A5: 1 | B5: โครงการพัฒนาศักยภาพนักศึกษาหลักสูตรบริหารธุรกิจ ภาค กศ.ปช. ประจำปีการศึกษา 2569 | C5: ='1.โครงการพัฒนาศักยภาพ บริหาร'!C7 -> 29200 | D5: ='1.โครงการพัฒนาศักยภาพ บริหาร'!D7 -> 28800 | E5: =C5-D5 -> 400 | F5: =D5*100/C5 -> 98.630137 | H5: 1โครงการพฒนานศ.บริหารธุรกิจ
A6: 2 | B6: โครงการพัฒนาทักษะการเรียนรู้ของผู้เรียนในศตวรรษที่ 21 โดยหลักนิติรัฐสำหรับชุมชน ของนักศึกษาภาคการศึกษาเพื่อปวงชน (กศ.ปช.) | C6: ='2.โครงพัฒนาทักษะ กศ.ปช'!D8 -> 21200 | D6: ='2.โครงพัฒนาทักษะ กศ.ปช'!E8 -> 3800 | E6: =C6-D6 -> 17400 | F6: =D6*100/C6 -> 17.924528 | H6: 2.โครงการพัฒนานักศึกษา กศ.ปช
A7: 3 | B7: โครงการพัฒนาศักยภาพและเสริมสร้างประสบการณ์การเรียนรู้เชิงนวัตกรรมหลักสูตรบริหารธุรกิจมหาบัณฑิตสาขาการจัดการธุรกิจและนวัตกรรม | C7: ='3.โครงการบริหารธุรกิจมหาบัณฑิต'!C7 -> 75200 | D7: ='3.โครงการบริหารธุรกิจมหาบัณฑิต'!D7 -> 75200 | E7: =C7-D7 -> 0 | F7: =D7*100/C7 -> 100 | H7: 3.โครงการพัฒนาศักยภาพบริหาร ป.โท
A8: 4 | B8: โครงการส่งเสริมและพัฒนานักศึกษาสาขาวิชารัฐประศาสนศาสตรมหาบัณฑิต | C8: ='4.โครงการ รปศ ป.โท'!C7 -> 12000 | D8: ='4.โครงการ รปศ ป.โท'!D7 -> 12000 | E8: =C8-D8 -> 0 | F8: =D8*100/C8 -> 100 | H8: 4.โครงการ รปศ. ป โท
A9: 5 | B9: โครงการพัฒนานักศึกษาบัณฑิตศึกษา เพื่อเสริมสร้างทักษะแห่งศตวรรษที่ 21 กลุ่มสาขาวิชาทางรัฐศาสตร์ | C9: ='5.โครงการ รัฐศาสตร์ ป.โท '!C7 -> 3200 | D9: ='5.โครงการ รัฐศาสตร์ ป.โท '!D7 -> 3200 | E9: =C9-D9 -> 0 | F9: =D9*100/C9 -> 100 | H9: 5.โครงการรัฐศาสตร์ ป.โท
A10: 6 | B10: โครงการจัดการเรียนการสอนระดับปริญญาตรีและระดับบัณฑิตศึกษา คณะศิลปศาสตร์และวิทยาศาสตร์ | C10: ='6.จัดการเรียนการสอนบัณฑิต'!C10 -> 3756000 | D10: ='6.จัดการเรียนการสอนบัณฑิต'!D10 -> 1676550 | E10: =C10-D10 -> 2079450 | F10: =D10*100/C10 -> 44.636581 | H10: 6.โครงการจัดการเรียนการสอน
A11: 7 | B11: โครงการนิเทศนักศึกษาฝึกประสบการณ์วิชาชีพ หรือสหกิจศึกษา คณะศิลปศาสตร์และวิทยาศาสตร์ ประจำปีงบประมาณ 2569 | C11: ='7.โครงการนิเทศ'!C7 -> 625300 | D11: ='7.โครงการนิเทศ'!D7 -> 575598 | E11: =C11-D11 -> 49702 | F11: =D11*100/C11 -> 92.051495 | H11: 7.โครงการนิเทศ
A12: 8 | B12: โครงการรับการตรวจประเมินคุณภาพการศึกษาภายใน คณะศิลปศาสตร์และวิทยาศาสตร์ ประจำปีการศึกษา 2568 | C12: ='8.โครงการรับประเมิน'!C7 -> 130000 | D12: ='8.โครงการรับประเมิน'!D7 -> 122786 | E12: =C12-D12 -> 7214 | F12: =D12*100/C12 -> 94.450769 | H12: 8.โครงการรับการตรวจประเมิน
A13: 9 | B13: โครงการบริหารจัดการคณะสู่ความเป็นเลิศ คณะศิลปศาสตร์และวิทยาศาสตร์ | C13: ='9.โครงการสู่ความเป็นเลิศ'!D15 -> 120600 | D13: ='9.โครงการสู่ความเป็นเลิศ'!E15 -> 120600 | E13: =C13-D13 -> 0 | F13: =D13*100/C13 -> 100 | H13: 9.โครงการบริหารจัดการสู๋ความเป็นเลิศ
A14: รวมทั้งสิ้น | C14: =SUM(C5:C13) -> 4772700 | D14: =SUM(D5:D13) -> 2618534 | E14: =SUM(E5:E13) -> 2154166 | F14: =D14*100/C14 -> 54.864835
B16: หมายเหตุ
B17: สรุปข้อมูล ณ วันที่ 11 สิงหาคม 2569 เวลา 15.30 น.

Sheet 1.โครงการพัฒนาศักยภาพ บริหาร
A1: โครงการพัฒนาศักยภาพนักศึกษาหลักสูตรบริหารธุรกิจ ภาค กศ.ปช. ประจำปีการศึกษา 2569 | F1: หน้าหลัก
A2: ระยะเวลาดำเนินโครงการ ไตรมาสที่ 2 - 4 (เดือน ม.ค. - ก.ย. 68)
A3: รหัสโครงการ | B3: ชื่อโครงการ | C3: งบประมาณ | D3: เบิก-จ่าย | E3: คงเหลือ
B4: ยอดเงินทั้งหมด | C4: 2900 | E4: =C4-D4 -> 2900
A5: กิจกรรมที่ 1.1 | B5: กิจกรรมที่ 1 : โครงการอบรมเชิงปฏิบัติการการเขียนแผนธุรกิจสำหรับผู้ประกอบการธุรกิจชุมชน | C5: ='กิจกรรมที่ 1.1'!D7 -> 14400 | D5: ='กิจกรรมที่ 1.1'!E7 -> 14400 | E5: =C5-D5 -> 0
A6: กิจกรรมที่ 1.2 | B6: กิจกรรมที่ 2 : โครงการพัฒนาผู้นำและจิตอาสา “นักจัดการเพื่อสังคม” | C6: ='กิจกรรมที่ 1.2'!D6 -> 14800 | D6: ='กิจกรรมที่ 1.2'!E6 -> 14400 | E6: =C6-D6 -> 400
A7: รวมทั้งสิ้น | C7: =SUM(C5:C6) -> 29200 | D7: =D5+D6 -> 28800 | E7: =C7-D7 -> 400

Sheet กิจกรรมที่ 1.1
A1: กิจกรรมที่ 1 : โครงการอบรมเชิงปฏิบัติการการเขียนแผนธุรกิจสำหรับผู้ประกอบการธุรกิจชุมชน | G1: โครงกาบริหารธุรกิจ
C2: ระยะเวลาดำเนินโครงการ ไตรมาสที่ 2 - 4 (เดือน ม.ค. - ก.ย. 68)
A3: ว/ด/ป/ | B3: ลำดับ | C3: รายการ | D3: รับ/อนุมัติ | E3: เบิก | F3: คงเหลือ
C4: กิจกรรมที่ 1 : โครงการอบรมเชิงปฏิบัติการการเขียนแผนธุรกิจสำหรับผู้ประกอบการธุรกิจชุมชน | D4: 14400 | F4: =D4-E4 -> 14400
A5: 086/69 | B5: 9 มี.ค.69 | C5: ค่าใช้จ่ายโครงการพัฒนาศักยภาพนักศึกษาหลักสูตรบริหารธุรกิจ ภาค กศ.ปช. ประจำปีการศึกษา 2569 กิจกรรมที่ 1 ในวันที่ 10 - 11 มกราคม 2569 ณ มหาวิทยาลัยราชภัฏชัยภูมิ (ค่าตอบแทนวิทยากร/ค่าอาหารกลางวัน/ค่าอาหารว่าง) ผศ.หทัยกาญจน์ ทองศรีสุข | E5: 14400 | F5: =F4+D5-E5 -> 0
F6: =F5+D6-E6 -> 0
A7: รวมทั้งสิ้น | D7: =SUM(D4:D6) -> 14400 | E7: =SUM(E4:E6) -> 14400 | F7: =D7-E7 -> 0
C9: *หมายเหตุ

Sheet กิจกรรมที่ 1.2
A1: กิจกรรมที่ 2 : โครงการพัฒนาผู้นำและจิตอาสา “นักจัดการเพื่อสังคม” | G1: โครงกาบริหารธุรกิจ
C2: ระยะเวลาดำเนินโครงการ ไตรมาสที่ 2 - 4 (เดือน ม.ค. - ก.ย. 68) | F2: =F4-D5 -> 14800
A3: ว/ด/ป/ | B3: ลำดับ | C3: รายการ | D3: รับ/อนุมัติ | E3: เบิก | F3: คงเหลือ
C4: กิจกรรมที่ 2 : โครงการพัฒนาผู้นำและจิตอาสา “นักจัดการเพื่อสังคม” | D4: 14800 | F4: =D4-E4 -> 14800
A5: 9 มี.ค.69 | B5: 087/69 | C5: ค่าใช้จ่ายโครงการพัฒนาศักยภาพนักศึกษาหลักสูตรบริหารธุรกิจ ภาค กศ.ปช. ประจำปีการศึกษา 2569 กิจกรรมที่ 2 ในวันที่ 17 - 18 มกราคม 2569 ณ มหาวิทยาลัยราชภัฏชัยภูมิ (ค่าตอบแทนวิทยากร/ค่าอาหารกลางวัน/ค่าอาหารว่าง) ผศ.หทัยกาญจน์ ทองศรีสุข | E5: 14400 | F5: =F4-E5 -> 400
A6: รวมทั้งสิ้น | D6: =D4 -> 14800 | E6: =SUM(E5:E5) -> 14400 | F6: =D6-E6 -> 400
C8: *หมายเหตุ

Sheet 2.โครงพัฒนาทักษะ กศ.ปช
A1: โครงการพัฒนาทักษะการเรียนรู้ของผู้เรียนในศตวรรษที่ 21 โดยหลักนิติรัฐสำหรับชุมชน ของนักศึกษาภาคการศึกษาเพื่อปวงชน (กศ.ปช.) | G1: หน้าหลัก
A2: ระยะเวลาดำเนินโครงการ ไตรมาสที่ 3 (เดือน เม.ย. - มิ.ย. 69)
A3: ว/ด/ป/ | B3: ลำดับ | C3: ชื่อโครงการ | D3: งบประมาณ | E3: เบิก-จ่าย | F3: คงเหลือ
C4: กิจกรรมที่ 1 : การเสวนาเชิงปฏิบัติการกลุ่มเพื่อพัฒนาทักษะการเรียนรู้ของผู้เรียนในศตวรรษที่ 21 ของนักศึกษาภาคการศึกษาเพื่อปวงชน (กศ.ปช.)สาขาวิชานิติศาสตร์ รัฐศาสตร์ รัฐประศาสนศาสตร์ และสหวิทยาการเพื่อการพัฒนาท้องถิ่น และถ่ายทอดองค์ความรู้สู่ชุมชน | D4: 21200 | F4: =D4-E4 -> 21200
A5: 15 ก.ย.69 | B5: 530/69 | C5: จัดซื้อวัสดุ จำนวน 6 รายการ โครงการพัฒนาทักษะการเรียนรู้ของผู้เรียนในศตวรรษที่ 21 โดยหลักนิติรัฐสำหรับชุมชน กิจกรรมที่ 1 (หจก.เมเจอร์คอม (2547)) อ.ดร.ณัฐปราย์ ชัยสินคุณานนต์ | E5: 3800 | F5: =F4-E5 -> 17400
F6: =F5-E6 -> 17400
F7: =F6-E7 -> 17400
A8: รวมทั้งสิ้น | D8: =SUM(D4:D7) -> 21200 | E8: =SUM(E4:E7) -> 3800 | F8: =SUM(F5:F7) -> 52200

Sheet 3.โครงการบริหารธุรกิจมหาบัณฑิต
A1: โครงการพัฒนาศักยภาพและเสริมสร้างประสบการณ์การเรียนรู้เชิงนวัตกรรมหลักสูตรบริหารธุรกิจมหาบัณฑิต สาขาการจัดการธุรกิจและนวัตกรรม | F1: หน้าหลัก
A2: ระยะเวลาดำเนินโครงการ ไตรมาสที่ 2 - 4 (เดือน ม.ค. - ก.ย. 68)
A3: รหัสโครงการ | B3: ชื่อโครงการ | C3: งบประมาณ | D3: เบิก-จ่าย | E3: คงเหลือ
B4: ยอดเงินทั้งหมด | C4: 75200 | E4: =C4-D4 -> 75200
A5: กิจกรรมที่ 3.1 | B5: กิจกรรมที่ 1 : ต้อนรับนักศึกษาใหม่ และเตรียมความพร้อมสำหรับ นักศึกษาชั้นปีที่ 1 | C5: ='กิจกรรมที่ 3.1'!D8 -> 19900 | D5: ='กิจกรรมที่ 3.1'!E8 -> 19900 | E5: =C5-D5 -> 0
A6: กิจกรรมที่ 3.2 | B6: กิจกรรมที่ 2 : ศึกษาดูงานด้านนวัตกรรมธุรกิจ | C6: ='กิจกรรมที่ 3.2'!D7 -> 55300 | D6: ='กิจกรรมที่ 3.2'!E7 -> 55300 | E6: =C6-D6 -> 0
A7: รวมทั้งสิ้น | C7: =SUM(C5:C6) -> 75200 | D7: =D5+D6 -> 75200 | E7: =C7-D7 -> 0

Sheet กิจกรรมที่ 3.1
A1: กิจกรรมที่ 1 : ต้อนรับนักศึกษาใหม่ และเตรียมความพร้อมสำหรับ นักศึกษาชั้นปีที่ 1 | G1: โครงกาบริหารธุรกิจ ป.โท
C2: ระยะเวลาดำเนินโครงการ ไตรมาสที่ 4 (เดือน ก.ค. - ก.ย. 69)
A3: ว/ด/ป/ | B3: ลำดับ | C3: รายการ | D3: รับ/อนุมัติ | E3: เบิก | F3: คงเหลือ
C4: กิจกรรมที่ 1 : ต้อนรับนักศึกษาใหม่ และเตรียมความพร้อมสำหรับ นักศึกษาชั้นปีที่ 1 | D4: 19900 | F4: =D4-E4 -> 19900
A5: 25 มิ.ย. 69 | B5: อว 0646.02/1056 ลงวันที่ 23 มิ.ย. 69 | C5: บันทึกข้อความ เรื่อง ขออนุญาตไปราชการโดย ผศ.ดร.สำเริง ไกยวงค์ พร้อมคณะ เดินทางไปราชการเพื่อรับ - ส่ง นักศึกษาต่างชาติ สัญชาติจีน ในวันที่ 7 กรกฎาคม 2569 ณ สนามบินสุวรรณภูมิ อำเภอบางพลี จังหวัดสมุทรปราการ | D5: 11200 | F5: =F4-E5 -> 19900
A6: 21 ส.ค. 69 | B6: 372/69 | C6: ค่าใช้จ่ายโครงการพัฒนาศักยภาพและเสริมสร้างประสบการณ์การเรียนรู้เชิงนวัตกรรมหลักสูตรบริหารธุรกิจมหาบัณฑิต สาขาการจัดการธุรกิจและนวัตกรรม วันที่ 8 กรกฎาคม 2569 ณ มหาวิทยาลัยราชภัฏชัยภูมิ (ค่าตอบแทนวิทยากร/ค่าอาหารกลางวัน/ค่าอาหารว่าง) ผศ.ดร.สำเริง ไกยวงค์ | E6: 8700 | F6: =F5-E6 -> 11200
A7: 21 ส.ค.69 | B7: 373/69 | C7: ค่าใช้จ่ายโครงการพัฒนาศักยภาพและเสริมสร้างประสบการณ์การเรียนรู้เชิงนวัตกรรมหลักสูตรบริหารธุรกิจมหาบัณฑิต สาขาการจัดการธุรกิจและนวัตกรรม กิจกรรมที่ 1 ในวันที่ 7 กรกฎาคม 2569 ณ สนามบินสุวรรณภูมิ (ค่าเบี้ยงเลี้ยง/ค่าน้ำมันเชื้อเพลิง) ผศ.ดร.สำเริง ไกยวงค์ | E7: 11200 | F7: =F6-E7 -> 0
A8: รวมทั้งสิ้น | D8: =D4 -> 19900 | E8: =SUM(E4:E7) -> 19900 | F8: =D8-E8 -> 0
C10: *หมายเหตุ
C11: ยกเลิกเลขหมายเลข 358/69 ยอด 19,900 บาท วันที่ 21 ส.ค. 69 แก้ไขเป็น เอกสาร 372/69 และ 373/69

Sheet กิจกรรมที่ 3.2
A1: กิจกรรมที่ 2 : ศึกษาดูงานด้านนวัตกรรมธุรกิจ | G1: โครงกาบริหารธุรกิจ ป.โท
C2: ระยะเวลาดำเนินโครงการ ไตรมาสที่ 2 - 4 (เดือน ม.ค. - ก.ย. 69)
A3: ว/ด/ป/ | B3: ลำดับ | C3: รายการ | D3: รับ/อนุมัติ | E3: เบิก | F3: คงเหลือ
C4: กิจกรรมที่ 2 : ศึกษาดูงานด้านนวัตกรรมธุรกิจ | D4: 55300 | F4: =D4-E4 -> 55300
A5: 27 ก.พ. 69 | B5: 066/69 | C5: ค่าใช้จ่ายเดินทางไปราชการโครงการพัฒนาศักยภาพและเสริมสร้างประสบการณ์การเรียนรู้เชิงนวัตกรรมหลักสูตรบริหารธุรกิจมหาบัณฑิตสาขาการจัดการธุรกิจและนวัตกรรม กิจกรรมที่ 2 วันที่ 18 - 20 กุมภาพันธ์ 2569 ณ จังหวัดอยุธยา ระยอง กรุงเทพมหานคร (ค่าเบี้ยเลี้ยง/ค่าที่พัก/ค่าน้ำมันเชื้อเพลิง) ผศ.ดร.อัญชลี ชัยศรี | E5: 55300 | F5: =F4+D5-E5 -> 0
F6: =F5+D6-E6 -> 0
A7: รวมทั้งสิ้น | D7: =SUM(D4:D6) -> 55300 | E7: =SUM(E4:E6) -> 55300 | F7: =D7-E7 -> 0
C9: *หมายเหตุ

Sheet 4.โครงการ รปศ ป.โท
A1: โครงการส่งเสริมและพัฒนานักศึกษาสาขาวิชารัฐประศาสนศาสตรมหาบัณฑิต | F1: หน้าหลัก
A2: ระยะเวลาดำเนินโครงการ ไตรมาสที่ 1 - 2 (เดือน ต.ค. 68 - มี.ค. 69)
A3: รหัสโครงการ | B3: ชื่อโครงการ | C3: งบประมาณ | D3: เบิก-จ่าย | E3: คงเหลือ
B4: ยอดเงินทั้งหมด | C4: 12000 | E4: =C4-D4 -> 12000
A5: กิจกรรมที่4.1 | B5: กิจกรรมที่ 1 : การพัฒนาทักษะการเขียนวิทยานิพนธ์และค้นคว้าอิสระ สาขาวิชารัฐประศาสนศาสตรมหาบัณฑิต | C5: ='กิจกรรมที่. 4.1'!D7 -> 6000 | D5: ='กิจกรรมที่. 4.1'!E7 -> 6000 | E5: =C5-D5 -> 0
A6: กิจกรรมที่4.2 | B6: กิจกรรมที่ 2 : การประยุกต์ใช้ AI ในการเขียนวิทยานิพนธ์และค้นคว้าอิสระ สาขาวิชารัฐประศาสนศาสตรมหาบัณฑิต | C6: =กิจกรรมที่.4.2!D6 -> 6000 | D6: =กิจกรรมที่.4.2!E6 -> 6000 | E6: =C6-D6 -> 0
A7: รวมทั้งสิ้น | C7: =SUM(C5:C6) -> 12000 | D7: =SUM(D5:D6) -> 12000 | E7: =C7-D7 -> 0

Sheet กิจกรรมที่. 4.1
A1: กิจกรรมที่ 1 : การพัฒนาทักษะการเขียนวิทยานิพนธ์และค้นคว้าอิสระ สาขาวิชารัฐประศาสนศาสตรมหาบัณฑิต | G1: รปศ. ปโท
C2: ระยะเวลาดำเนินโครงการ ในไตรมาสที่ 1 ( ต.ค. - ธ.ค. 69)
A3: ว/ด/ป/ | B3: ลำดับ | C3: รายการ | D3: รับ/อนุมัติ | E3: เบิก | F3: คงเหลือ
C4: กิจกรรมที่ 1 : การพัฒนาทักษะการเขียนวิทยานิพนธ์และค้นคว้าอิสระ สาขาวิชารัฐประศาสนศาสตรมหาบัณฑิต | D4: 6000 | F4: =D4-E4 -> 6000
A5: 19 ก.พ. 69 | B5: 053/69 | C5: ค่าใช้จ่ายโครงการส่งเสริมและพัฒนานักศึกษาสาขาวิชารัฐประศาสนศาสตรมหาบัณฑิต ระหว่างวันที่ 14 - 15 กุมภาพันธ์ 2569 กิจกรรมที่ 1 วันที่ 14 กุมภาพันธ์ 2569 ณ ห้องเรียนต้นแบบในศตวรรษที่ 21 อาคารปฏิบัติการเทคโนโลยีอุตสาหกรรม (ค่าตอบแทนวิทยากร/อาหารว่าง/อาหารกลางวัน) ผศ.ดร.สมปอง สุวรรณภูมา | E5: 6000 | F5: =F4+D5-E5 -> 0
A7: รวมทั้งสิ้น | D7: =SUM(D4:D5) -> 6000 | E7: =SUM(E4:E6) -> 6000 | F7: =D7-E7 -> 0
C9: *หมายเหตุ

Sheet กิจกรรมที่.4.2
A1: กิจกรรมที่ 2 : การประยุกต์ใช้ AI ในการเขียนวิทยานิพนธ์และค้นคว้าอิสระ สาขาวิชารัฐประศาสนศาสตรมหาบัณฑิต | G1: รปศ. ปโท
C2: ระยะเวลาดำเนินโครงการ ในไตรมาสที่ 2 ( ม.ค. - มี.ค. 69)
A3: ว/ด/ป/ | B3: ลำดับ | C3: รายการ | D3: รับ/อนุมัติ | E3: เบิก | F3: คงเหลือ
C4: กิจกรรมที่ 2 : การประยุกต์ใช้ AI ในการเขียนวิทยานิพนธ์และค้นคว้าอิสระ สาขาวิชารัฐประศาสนศาสตรมหาบัณฑิต | D4: 6000 | F4: =D4-E4 -> 6000
A5: 19 ก.พ. 69 | B5: 053/69 | C5: ค่าใช้จ่ายโครงการส่งเสริมและพัฒนานักศึกษาสาขาวิชารัฐประศาสนศาสตรมหาบัณฑิต ระหว่างวันที่ 14 - 15 กุมภาพันธ์ 2569 กิจกรรมที่ 2 วันที่ 15 กุมภาพันธ์ 2569 ณ ห้องเรียนต้นแบบในศตวรรษที่ 21 อาคารปฏิบัติการเทคโนโลยีอุตสาหกรรม (ค่าตอบแทนวิทยากร/อาหารว่าง/อาหารกลางวัน) ผศ.ดร.สมปอง สุวรรณภูมา | E5: 6000 | F5: =F4+D5-E5 -> 0
A6: รวมทั้งสิ้น | D6: =SUM(D4:D5) -> 6000 | E6: =SUM(E4:E5) -> 6000 | F6: =D6-E6 -> 0
C8: *หมายเหตุ

Sheet 5.โครงการ รัฐศาสตร์ ป.โท 
A1: โครงการพัฒนานักศึกษาบัณฑิตศึกษา เพื่อเสริมสร้างทักษะแห่งศตวรรษที่ 21 กลุ่มสาขาวิชาทางรัฐศาสตร์ | F1: หน้าหลัก
A2: ระยะเวลาดำเนินโครงการ ไตรมาสที่ 2 (เดือน ม.ค. - มี.ค. 69)
A3: รหัสโครงการ | B3: ชื่อโครงการ | C3: งบประมาณ | D3: เบิก-จ่าย | E3: คงเหลือ
B4: ยอดเงินทั้งหมด | C4: 3200 | E4: =C4-D4 -> 3200
A5: กิจกรรมที่5.1 | B5: กิจกรรมที่ 1 : การพัฒนาวิทยานิพนธ์ของนักศึกษา สาขาวิชารัฐศาสตรมหาบัณฑิต | C5: ='กิจกรรมที่ 5.1'!D6 -> 1600 | D5: ='กิจกรรมที่ 5.1'!E6 -> 1600 | E5: =C5-D5 -> 0
A6: กิจกรรมที่5.2 | B6: กิจกรรมที่2 : พัฒนาทักษะการเขียนผลงานวิจัยเพื่อเผยแพร่ สาขาวิชารัฐศาสตรดุษฎีบัณฑิต | C6: ='กิจกรรมที่ 5.2'!D6 -> 1600 | D6: ='กิจกรรมที่ 5.2'!E6 -> 1600 | E6: =C6-D6 -> 0
A7: รวมทั้งสิ้น | C7: =SUM(C5:C6) -> 3200 | D7: =SUM(D5:D6) -> 3200 | E7: =C7-D7 -> 0

Sheet กิจกรรมที่ 5.1
A1: กิจกรรมที่ 1 : การพัฒนาวิทยานิพนธ์ของนักศึกษา สาขาวิชารัฐศาสตรมหาบัณฑิต | G1: รัฐศาสตร์ ป.โท
C2: ระยะเวลาดำเนินโครงการ ในไตรมาสที่ 2 ( ม.ค. - มี.ค. 69)
A3: ว/ด/ป/ | B3: ลำดับ | C3: รายการ | D3: รับ/อนุมัติ | E3: เบิก | F3: คงเหลือ
C4: กิจกรรมที่ 1 : การพัฒนาวิทยานิพนธ์ของนักศึกษา สาขาวิชารัฐศาสตรมหาบัณฑิต | D4: 1600 | F4: =D4-E4 -> 1600
A5: 24 ส.ค. 69 | B5: 379/69 | C5: ค่าใช้จ่ายโครงการพัฒนานักศึกษาบัณฑิตศึกษา เพื่อเสริมสร้างทักษะแห่งศตวรรษที่ 21 กลุ่มสาขาวิชาทางรัฐศาสตร์ กิจกรรมที่ 1 ในวันที่ 10 พฤษภาคม 2569 ณ ศูนย์ฝึกประสบการณ์วิชาชีพบริหารธุรกิจการท่องเที่ยวและโรงแรม PHUM RAJABHAT HILL ภูมิราชภัฏฮิลล์ มหาวิทยาลัยราชภัฏชัยภูมิ (ค่าตอบแทนวิทยากร/ค่าอาหารกลางวัน) ผศ.ดร.ณัฐดนัย แก้วโพนงาม | E5: 1600 | F5: =F4+D5-E5 -> 0
A6: รวมทั้งสิ้น | D6: =SUM(D4:D5) -> 1600 | E6: =SUM(E4:E5) -> 1600 | F6: =D6-E6 -> 0
C8: *หมายเหตุ

Sheet กิจกรรมที่ 5.2
A1: กิจกรรมที่2 : พัฒนาทักษะการเขียนผลงานวิจัยเพื่อเผยแพร่ สาขาวิชารัฐศาสตรดุษฎีบัณฑิต | G1: รัฐศาสตร์ ป.โท
C2: ระยะเวลาดำเนินโครงการ ในไตรมาสที่ 2 ( ม.ค. - มี.ค. 68)
A3: ว/ด/ป/ | B3: ลำดับ | C3: รายการ | D3: รับ/อนุมัติ | E3: เบิก | F3: คงเหลือ
C4: กิจกรรมที่2 : พัฒนาทักษะการเขียนผลงานวิจัยเพื่อเผยแพร่ สาขาวิชารัฐศาสตรดุษฎีบัณฑิต | D4: 1600 | F4: =D4-E4 -> 1600
A5: 24 ส.ค. 69 | B5: 380/69 | C5: ค่าใช้จ่ายโครงการพัฒนานักศึกษาบัณฑิตศึกษา เพื่อเสริมสร้างทักษะแห่งศตวรรษที่ 21 กลุ่มสาขาวิชาทางรัฐศาสตร์ กิจกรรมที่ 2 ในวันที่ 11 พฤษภาคม 2569 ณ ศูนย์ฝึกประสบการณ์วิชาชีพบริหารธุรกิจการท่องเที่ยวและโรงแรม PHUM RAJABHAT HILL ภูมิราชภัฏฮิลล์ มหาวิทยาลัยราชภัฏชัยภูมิ (ค่าตอบแทนวิทยากร/ค่าอาหารกลางวัน/ค่าอาหารว่าง) ผศ.ดร.ณัฐดนัย แก้วโพนงาม | E5: 1600 | F5: =F4-E5 -> 0
A6: รวมทั้งสิ้น | D6: =D4 -> 1600 | E6: =SUM(E4:E5) -> 1600 | F6: =D6-E6 -> 0
C8: *หมายเหตุ

Sheet 6.จัดการเรียนการสอนบัณฑิต
A1: โครงการจัดการเรียนการสอนระดับปริญญาตรีและระดับบัณฑิตศึกษา คณะศิลปศาสตร์และวิทยาศาสตร์ | F1: หน้าหลัก
A2: ระยะเวลาดำเนินโครงการ ไตรมาสที่ 1 - 4 (เดือน ต.ค. 67 - ก.ย. 68)
A3: รหัสโครงการ | B3: ชื่อโครงการ | C3: งบประมาณ | D3: เบิก-จ่าย | E3: คงเหลือ
B4: ยอดเงินทั้งหมด | C4: 3756000 | E4: =C4-D4 -> 3756000
A5: กิจกรรมที่ 6.1 | B5: กิจกรรมที่ 1 : จัดการเรียนการสอน หลักสูตรบริหารธุรกิจมหาบัณฑิต และหลักสูตรบริหารธุรกิจดุษฎีบัณฑิต สาขาวิชาการจัดการธุรกิจและนวัตกรรม | C5: ='กิจกรรมที่ 6.1.'!D38 -> 1128500 | D5: ='กิจกรรมที่ 6.1.'!E38 -> 458000 | E5: =C5-D5 -> 670500
A6: กิจกรรมที่ 6.2 | B6: กิจกรรมที่ 2 : จัดการเรียนการสอน หลักสูตรรัฐประศาสนศาสตร์มหาบัณฑิต สาขาวิชารัฐประศาสนศาสตร์ | C6: ='กิจกรรมที่ 6.2.'!D17 -> 743000 | D6: ='กิจกรรมที่ 6.2.'!E17 -> 260000 | E6: =C6-D6 -> 483000
A7: กิจกรรมที่ 6.3 | B7: กิจกรรมที่ 3 : จัดการเรียนการสอน หลักสูตรรัฐศาสตร์มหาบัณฑิต | C7: ='กิจกรรมที่ 6.3.'!D16 -> 569000 | D7: ='กิจกรรมที่ 6.3.'!E16 -> 171100 | E7: =C7-D7 -> 397900
A8: กิจกรรมที่ 6.4 | B8: กิจกรรมที่ 4 : จัดการเรียนการสอน หลักสูตรรัฐศาสตรดุษฎีบัณฑิต | C8: ='กิจกรรมที่ 6.4.'!D31 -> 1137000 | D8: ='กิจกรรมที่ 6.4.'!E31 -> 608950 | E8: =C8-D8 -> 528050
A9: กิจกรรมที่ 6.5 | B9: กิจกรรมที่ 5 : จัดการเรียนการสอน ระดับปริญญาตรี | C9: ='กิจกรรมที่ 6.5.'!D19 -> 178500 | D9: ='กิจกรรมที่ 6.5.'!E19 -> 178500 | E9: =C9-D9 -> 0
A10: รวมทั้งสิ้น | C10: =SUM(C5:C9) -> 3756000 | D10: =SUM(D5:D9) -> 1676550 | E10: =C10-D10 -> 2079450
A12: ผู้รับผิดชอบโครงการ

Sheet กิจกรรมที่ 6.1.
A1: กิจกรรมที่ 1 : จัดการเรียนการสอน หลักสูตรบริหารธุรกิจมหาบัณฑิต และหลักสูตรบริหารธุรกิจดุษฎีบัณฑิต สาขาวิชาการจัดการธุรกิจและนวัตกรรม | G1: โครงการจัดการเรียนการสอน
C2: ระยะเวลาดำเนินโครงการ ไตรมาสที่ 1 - 4 (เดือน ต.ค. 68 - ก.ย. 69)
A3: ว/ด/ป/ | B3: ลำดับ | C3: รายการ | D3: รับ/อนุมัติ | E3: เบิก | F3: คงเหลือ
C4: กิจกรรมที่ 1 : จัดการเรียนการสอน หลักสูตรบริหารธุรกิจมหาบัณฑิต และหลักสูตรบริหารธุรกิจดุษฎีบัณฑิต สาขาวิชาการจัดการธุรกิจและนวัตกรรม | D4: 1128500 | F4: =D4-E4 -> 1128500
A5: 6 มี.ค.69 | B5: 079/69 | C5: ค่าตอบแทนการสอบโครงร่างการค้นคว้าอิสระระดับปริญญาโท หลักสูตรบริหารธุรกิจมหาบัณฑฺต สาขาวิชาการจัดการธุรกิจและนวัตกรรม โครงการจัดการเรียนการสอนระดับปริญญาตรีและระดับบัณฑิตศึกษา คณะศิลปศาสตร์และวิทยาศาสตร์ กิจกรรมที่ 1 (ผศ.ดร.สำเริง ไกยวงค์) | E5: 10400 | F5: =F4+D5-E5 -> 1118100
A6: 6 มี.ค.69 | B6: 080/69 | C6: ค่าตอบแทนการสอบโครงร่างการค้นคว้าอิสระระดับปริญญาโท หลักสูตรบริหารธุรกิจมหาบัณฑฺต สาขาวิชาการจัดการธุรกิจและนวัตกรรม โครงการจัดการเรียนการสอนระดับปริญญาตรีและระดับบัณฑิตศึกษา คณะศิลปศาสตร์และวิทยาศาสตร์ กิจกรรมที่ 1 (ผศ.ดร.สำเริง ไกยวงค์) | E6: 13000 | F6: =F5+D6-E6 -> 1105100
A7: 6 มี.ค.69 | B7: 081/69 | C7: ค่าตอบแทนการสอบโครงร่างการค้นคว้าอิสระระดับปริญญาโท หลักสูตรบริหารธุรกิจมหาบัณฑฺต สาขาวิชาการจัดการธุรกิจและนวัตกรรม โครงการจัดการเรียนการสอนระดับปริญญาตรีและระดับบัณฑิตศึกษา คณะศิลปศาสตร์และวิทยาศาสตร์ กิจกรรมที่ 1 (อ.ดร.รจนา เมืองแสน) | E7: 5200 | F7: =F6+D7-E7 -> 1099900
A8: 6 มี.ค.69 | B8: 082/69 | C8: ค่าตอบแทนการสอบโครงร่างการค้นคว้าอิสระระดับปริญญาโท หลักสูตรบริหารธุรกิจมหาบัณฑฺต สาขาวิชาการจัดการธุรกิจและนวัตกรรม โครงการจัดการเรียนการสอนระดับปริญญาตรีและระดับบัณฑิตศึกษา คณะศิลปศาสตร์และวิทยาศาสตร์ กิจกรรมที่ 1 (ผศ.ดร.อัญชลี ชัยศรี) | E8: 10400 | F8: =F7+D8-E8 -> 1089500
A9: 6 มี.ค.69 | B9: 083/69 | C9: ค่าตอบแทนการสอบโครงร่างการค้นคว้าอิสระระดับปริญญาโท หลักสูตรบริหารธุรกิจมหาบัณฑฺต สาขาวิชาการจัดการธุรกิจและนวัตกรรม โครงการจัดการเรียนการสอนระดับปริญญาตรีและระดับบัณฑิตศึกษา คณะศิลปศาสตร์และวิทยาศาสตร์ กิจกรรมที่ 1 (อ.ดร.สำราญ วานนท์) | E9: 10400 | F9: =F8+D9-E9 -> 1079100
A10: 6 มี.ค.69 | B10: 084/69 | C10: ค่าตอบแทนการสอบโครงร่างการค้นคว้าอิสระระดับปริญญาโท หลักสูตรบริหารธุรกิจมหาบัณฑฺต สาขาวิชาการจัดการธุรกิจและนวัตกรรม โครงการจัดการเรียนการสอนระดับปริญญาตรีและระดับบัณฑิตศึกษา คณะศิลปศาสตร์และวิทยาศาสตร์ กิจกรรมที่ 1 (ผศ.ดร.ทัศไนยวรรณ ดวงมาลา) | E10: 5200 | F10: =F9+D10-E10 -> 1073900
A11: 6 มี.ค.69 | B11: 085/69 | C11: ค่าตอบแทนการสอบโครงร่างการค้นคว้าอิสระระดับปริญญาโท หลักสูตรบริหารธุรกิจมหาบัณฑฺต สาขาวิชาการจัดการธุรกิจและนวัตกรรม โครงการจัดการเรียนการสอนระดับปริญญาตรีและระดับบัณฑิตศึกษา คณะศิลปศาสตร์และวิทยาศาสตร์ กิจกรรมที่ 1 (อ.ดร.สำราญ วานนท์) | E11: 10400 | F11: =F10+D11-E11 -> 1063500
A12: 23 เม.ย.69 | B12: 151/69 | C12: ค่าตอบแทนการสอนระดับปริญญาโท หลักสูตรบริหารธุรกิจมหาบัณฑิต สาขาวิชาการธุรกิจและนวัตกรรม โครงการจัดการเรียนการสอนระดับปริญญาตรีและระดับบัณฑิตศึกษา คณะศิลปศาสตร์และวิทยาศาสตร์ กิจกรรมที่ 1 ภาคเรียนที่ 2/2568 อ.ดร.เฉลิมวุฒิ อุทัยกัน | E12: 27000 | F12: =F11+D12-E12 -> 1036500
A13: 23 เม.ย.69 | B13: 152/69 | C13: ค่าตอบแทนการสอนระดับปริญญาโท หลักสูตรบริหารธุรกิจมหาบัณฑิต สาขาวิชาการธุรกิจและนวัตกรรม โครงการจัดการเรียนการสอนระดับปริญญาตรีและระดับบัณฑิตศึกษา คณะศิลปศาสตร์และวิทยาศาสตร์ กิจกรรมที่ 1 ภาคเรียนที่ 2/2568 ผศ.ดร.อัญชลี ชัยศรี | E13: 36000 | F13: =F12+D13-E13 -> 1000500
A14: 23 เม.ย.69 | B14: 159/69 | C14: ค่าตอบแทนการสอนระดับปริญญาโท หลักสูตรบริหารธุรกิจมหาบัณฑิต สาขาวิชาการจัดการธุรกิจและนวัตกรรม โครงการจัดการเรียนการสอนระดับปริญญาตรีและระดับบัณฑิตศึกษา คณะศิลปศาสตร์และวิทยาศาสตร์ กิจกรรมที่ 1 ภาคเรียนที่ 2/2568 ผศ.ดร.สำเริง ไกยวงค์ | E14: 34000 | F14: =F13+D14-E14 -> 966500 | G14: แก้ไขยอดจากเดิม 36,000เป็น 34,000บาท 5 พ.ค.69
A15: 23 เม.ย.69 | B15: 160/69 | C15: ค่าตอบแทนการสอนระดับปริญญาโท หลักสูตรบริหารธุรกิจมหาบัณฑิต สาขาวิชาการจัดการธุรกิจและนวัตกรรม โครงการจัดการเรียนการสอนระดับปริญญาตรีและระดับบัณฑิตศึกษา คณะศิลปศาสตร์และวิทยาศาสตร์ กิจกรรมที่ 1 ภาคเรียนที่ 2/2568 ผศ.ดร.สำเริง ไกยวงค์ | E15: 34000 | F15: =F14+D15-E15 -> 932500
A16: 23 เม.ย.69 | B16: 161/69 | C16: ค่าตอบแทนการสอนระดับปริญญาโท หลักสูตรบริหารธุรกิจมหาบัณฑิต สาขาวิชาการจัดการธุรกิจและนวัตกรรม โครงการจัดการเรียนการสอนระดับปริญญาตรีและระดับบัณฑิตศึกษา คณะศิลปศาสตร์และวิทยาศาสตร์ กิจกรรมที่ 1 ภาคเรียนที่ 2/2568 ผศ.ดร.สำเริง ไกยวงค์ | E16: 27000 | F16: =F15+D16-E16 -> 905500
A17: 17 ก.ค. 69 | B17: 312/69 | C17: ค่าตอบแทนอาจารย์ที่ปรึกษาระดับปริญญาโท หลักสูตรบริหารธุรกิจมหาบัณฑิต สาขาวิชาการจัดการธุรกิจและนวัตกรรม โครงการจัดการเรียนการสอนระดับปริญญาตรีและระดับบัณฑิตศึกษา คณะศิลปศาสตร์และวิทยาศาสตร์ กิจกรรมที่ 1อาจารย์ ดร.สำราญ วานนท์ | E17: 4500 | F17: =F16+D17-E17 -> 901000
A18: 17 ก.ค. 69 | B18: 313/69 | C18: ค่าตอบแทนการสอบโครงร่างวิทยานิพนธ์ระดับปริญญาโท หลักสูตรบริหารธุรกิจมหาบัณฑฺต สาขาวิชาการจัดการธุรกิจและนวัตกรรม นายปัญจรุจน์ วัชรจรัสภัสร์โครงการจัดการเรียนการสอนระดับปริญญาตรีและระดับบัณฑิตศึกษา คณะศิลปศาสตร์และวิทยาศาสตร์ กิจกรรมที่ 1 (ผศ.ดร.อัญชลี ชัยศรี) | E18: 3500 | F18: =F17+D18-E18 -> 897500
A19: 17 ก.ค. 69 | B19: 314/69 | C19: ค่าตอบแทนที่ปรึกษาการค้นคว้าอิสระระดับปริญญาโท หลักสูตรบริหารธุรกิจมหาบัณฑฺต สาขาวิชาการจัดการธุรกิจและนวัตกรรม Ms.Rong Zhang โครงการจัดการเรียนการสอนระดับปริญญาตรีและระดับบัณฑิตศึกษา คณะศิลปศาสตร์และวิทยาศาสตร์ กิจกรรมที่ 1 (ผศ.ดร.อัญชลี ชัยศรี) | E19: 4500 | F19: =F18+D19-E19 -> 893000
A20: 17 ก.ค. 69 | B20: 315/69 | C20: ค่าตอบแทนอาจารย์ที่ปรึกษาระดับปริญญาโท หลักสูตรบริหารธุรกิจมหาบัณฑิต สาขาวิชาการจัดการธุรกิจและนวัตกรรม จำนวน 2 คน โครงการจัดการเรียนการสอนระดับปริญญาตรีและระดับบัณฑิตศึกษา คณะศิลปศาสตร์และวิทยาศาสตร์ กิจกรรมที่ 1(ผศ.ดร.สำเริง ไกยวงค์) | E20: 9000 | F20: =F19+D20-E20 -> 884000
A21: 17 ก.ค. 69 | B21: 316/69 | C21: ค่าตอบแทนการสอบโครงร่างวิทยานิพนธ์ระดับปริญญาโท หลักสูตรบริหารธุรกิจมหาบัณฑฺต สาขาวิชาการจัดการธุรกิจและนวัตกรรม นายจิราเจต ลิ้มภักดี โครงการจัดการเรียนการสอนระดับปริญญาตรีและระดับบัณฑิตศึกษา คณะศิลปศาสตร์และวิทยาศาสตร์ กิจกรรมที่ 1 (ผศ.ดร.สำเริง ไกยวงค์) | E21: 3500 | F21: =F20+D21-E21 -> 880500
A22: 25 ส.ค. 69 | B22: 390/69 | C22: ค่าตอบแทนอาจารย์ที่ปรึกษาการค้นคว้าอิสระ ระดับปริญญาโท หลักสูตรบริหารธุรกิจมหาบัณฑิต สาขาวิชาการจัดการธุรกิจและนวัตกรรม จำนวน 2 คน โครงการจัดการเรียนการสอนระดับปริญญาตรีและระดับบัณฑิตศึกษา คณะศิลปศาสตร์และวิทยาศาสตร์ กิจกรรมที่ 1(อาจารย์ ดร.รจนา เมืองแสน) | E22: 9000 | F22: =F21+D22-E22 -> 871500
A23: 25 ส.ค. 69 | B23: 391/69 | C23: ค่าตอบแทนอาจารย์ที่ปรึกษาการค้นคว้าอิสระ ระดับปริญญาโท หลักสูตรบริหารธุรกิจมหาบัณฑิต สาขาวิชาการจัดการธุรกิจและนวัตกรรม จำนวน 2 คน โครงการจัดการเรียนการสอนระดับปริญญาตรีและระดับบัณฑิตศึกษา คณะศิลปศาสตร์และวิทยาศาสตร์ กิจกรรมที่ 1(ผศ.ดร.ทัศไนยวรรณ ดวงมาลา) | E23: 9000 | F23: =F22+D23-E23 -> 862500
A24: 25 ส.ค. 69 | B24: 392/69 | C24: ค่าตอบแทนอาจารย์ที่ปรึกษาการค้นคว้าอิสระ ระดับปริญญาโท หลักสูตรบริหารธุรกิจมหาบัณฑิต สาขาวิชาการจัดการธุรกิจและนวัตกรรม จำนวน 4 คน โครงการจัดการเรียนการสอนระดับปริญญาตรีและระดับบัณฑิตศึกษา คณะศิลปศาสตร์และวิทยาศาสตร์ กิจกรรมที่ 1(อ.ดร.สำราญ วานนท์) | E24: 18000 | F24: =F23+D24-E24 -> 844500
A25: 25 ส.ค. 69 | B25: 393/69 | C25: ค่าตอบแทนอาจารย์ที่ปรึกษาการค้นคว้าอิสระ ระดับปริญญาโท หลักสูตรบริหารธุรกิจมหาบัณฑิต สาขาวิชาการจัดการธุรกิจและนวัตกรรม จำนวน 8 คน โครงการจัดการเรียนการสอนระดับปริญญาตรีและระดับบัณฑิตศึกษา คณะศิลปศาสตร์และวิทยาศาสตร์ กิจกรรมที่ 1(ผศ.ดร.อัญชลี ชัยศรี) | E25: 36000 | F25: =F24+D25-E25 -> 808500
A26: 25 ส.ค. 69 | B26: 394/69 | C26: ค่าตอบแทนอาจารย์ที่ปรึกษาการค้นคว้าอิสระ ระดับปริญญาโท หลักสูตรบริหารธุรกิจมหาบัณฑิต สาขาวิชาการจัดการธุรกิจและนวัตกรรม จำนวน 9 คน โครงการจัดการเรียนการสอนระดับปริญญาตรีและระดับบัณฑิตศึกษา คณะศิลปศาสตร์และวิทยาศาสตร์ กิจกรรมที่ 1(ผศ.ดร.สำเริง ไกยวงค์) | E26: 40500 | F26: =F25+D26-E26 -> 768000
... A37: 15 ก.ย. 69 | B37: 527/69 | C37: ค่าตอบแทนการสอบวิทยานิพนธ์ ระดับปริญญาโท หลักสูตรบริหารธุรกิจมหาบัณฑิต สาขาวิชาการจัดการธรุกิจและนวัตกรรม วันที่ 5 กันยายน 2569 โครงการจัดการเรียนการสอนระดับปริญญาตรีและระดับบัณฑิตศึกษา คณะศิลปศาสตร์และวิทยาศาสตร์ กิจกรรมที่ 1 (ผศ.ดร.สำเริง ไกยวงค์) | E37: 5000 | F37: =F36+D37-E37 -> 661600
A38: รวมทั้งสิ้น | D38: =SUM(D4:D9) -> 1128500 | E38: =SUM(E5:E35) -> 458000 | F38: =D38-E38 -> 670500
C40: *หมายเหตุ | E40: เงินกัน | F40: คงเหลือ
C41: กันเงินค่าตอบแทนการสอน จำนวน 374,500 บาท | E41: 374500 | F41: =F38-E41 -> 296000

Sheet กิจกรรมที่ 6.2.
A1: กิจกรรมที่ 2 : จัดการเรียนการสอน หลักสูตรรัฐประศาสนศาสตร์มหาบัณฑิต สาขาวิชารัฐประศาสนศาสตร์ | G1: โครงการจัดการเรียนการสอน
C2: ระยะเวลาดำเนินโครงการ ไตรมาสที่ 1 - 4 (เดือน ต.ค. 68 - ก.ย. 69)
A3: ว/ด/ป/ | B3: ลำดับ | C3: รายการ | D3: รับ/อนุมัติ | E3: เบิก | F3: คงเหลือ
C4: กิจกรรมที่ 2 : จัดการเรียนการสอน หลักสูตรรัฐประศาสนศาสตร์มหาบัณฑิต สาขาวิชารัฐประศาสนศาสตร์ | D4: 743000 | F4: =D4-E4 -> 743000
A5: 067/69 | B5: 27 ก.พ.69 | C5: ค่าตอบแทนการสอบวิทยานิพนธ์ระดับปริญญาโท หลักสูตรรัฐประศาสนศาสตรมหาบัณฑิต สาขาวิชารัฐประศาสนศาสตร์ จำนวน 3 ราย โครงการจัดการเรียนการสอนระดับปริญญาตรีและระดับบัณฑิตศึกษา คณะศิลปสาสตร์และวิทยาศาสตร์ กิจกรรมที่ 2 (ผศ.ดร.สมปอง สุวรรณภูมา) | E5: 15000 | F5: =F4+D5-E5 -> 728000
A6: 153/69 | B6: 23 เม.ย.69 | C6: ค่าตอบแทนการสอนระดับปริญญาโท หลักสูตรรัฐประศาสนศาสตร์มหาบัณฑิต สาขาวิชารัฐประศาสนศาสตร์ โครงการจัดการเรียนการสอนระดับปริญญาตรีและระดับบัณฑิตศึกษา คณะศิลปศาสตร์และวิทยาศาสตร์ กิจกรรมที่ 2 ภาคเรียนที่ 2/2568 ผศ.ดร.ธิติรัตน์ เหล่าคมพฤฒาจารย์ | E6: 27000 | F6: =F5+D6-E6 -> 701000
A7: 154/69 | B7: 23 เม.ย.69 | C7: ค่าตอบแทนการสอนระดับปริญญาโท หลักสูตรรัฐประศาสนศาสตร์มหาบัณฑิต สาขาวิชารัฐประศาสนศาสตร์ โครงการจัดการเรียนการสอนระดับปริญญาตรีและระดับบัณฑิตศึกษา คณะศิลปศาสตร์และวิทยาศาสตร์ กิจกรรมที่ 2 ภาคเรียนที่ 2/2568 ผศ.ดร.สมปอง สุวรรณภูมา | E7: 25500 | F7: =F6+D7-E7 -> 675500 | G7: แก้ไขยอดจากเดิม 24,000 เป็น 25,500 บาท 5 พ.ค.69
A8: 155/69 | B8: 23 เม.ย.69 | C8: ค่าตอบแทนการสอนระดับปริญญาโท หลักสูตรรัฐประศาสนศาสตร์มหาบัณฑิต สาขาวิชารัฐประศาสนศาสตร์ โครงการจัดการเรียนการสอนระดับปริญญาตรีและระดับบัณฑิตศึกษา คณะศิลปศาสตร์และวิทยาศาสตร์ กิจกรรมที่ 2 ภาคเรียนที่ 2/2568 ผศ.ดร.สมปอง สุวรรณภูมา | E8: 27000 | F8: =F7+D8-E8 -> 648500
A9: 208/69 | B9: 18 พ.ค. 69 | C9: ค่าตอบแทนการสอนระดับปริญญาโท หลักสูตรรัฐประศาสนศาสตร์มหาบัณฑิต สาขาวิชารัฐประศาสนศาสตร์ โครงการจัดการเรียนการสอนระดับปริญญาตรีและระดับบัณฑิตศึกษา คณะศิลปศาสตร์และวิทยาศาสตร์ กิจกรรมที่ 2 ภาคเรียนที่ 2/2568 ผศ.ดร.ลักขณา สุกใส | E9: 25500 | F9: =F8+D9-E9 -> 623000
A10: 317/69 | B10: 17 ก.ค. 69 | C10: ค่าตอบแทนอาจารย์ที่ปรึกษาวิทยานิพนธ์ระดับปริญญาโท หลักสูตรรัฐประศาสนศาสตร์มหาบัณฑิต สาขาวิชารัฐประศาสนศาสตร จำนวน 1 คน โครงการจัดการเรียนการสอนระดับปริญญาตรีและระดับบัณฑิตศึกษา คณะศิลปศาสตร์และวิทยาศาสตร์ กิจกรรมที่ 2 (รศ.ดร.พิทักษ์พงศ์ กางการ) | E10: 4500 | F10: =F9+D10-E10 -> 618500
A11: 318/69 | B11: 17 ก.ค. 69 | C11: ค่าตอบแทนการสอบวิทยานิพนธ์ระดับปริญญาโท หลักสูตรรัฐประศาสนศาสตร์มหาบัณฑิต สาขาวิชารัฐประศาสนศาสตร จำนวน 1 คน นายกิตติวันท์ ภาคภูมิ โครงการจัดการเรียนการสอนระดับปริญญาตรีและระดับบัณฑิตศึกษา คณะศิลปศาสตร์และวิทยาศาสตร์ กิจกรรมที่ 2 (ผศ.ดร.สมปอง สุวรรณภูมา) | E11: 5000 | F11: =F10+D11-E11 -> 613500
A12: 319/69 | B12: 17 ก.ค. 69 | C12: ค่าตอบแทนการสอนระดับปริญญาโท หลักสูตรรัฐประศาสนศาสตร์มหาบัณฑิต สาขาวิชารัฐประศาสนศาสตร ภาคเรียนที่ 3/2568 โครงการจัดการเรียนการสอนระดับปริญญาตรีและระดับบัณฑิตศึกษา คณะศิลปศาสตร์และวิทยาศาสตร์ กิจกรรมที่ 2 (ผศ.ดร.สมปอง สุวรรณภูมา) | E12: 24750 | F12: =F11+D12-E12 -> 588750
A13: 320/69 | B13: 17 ก.ค. 69 | C13: ค่าตอบแทนการสอนระดับปริญญาโท หลักสูตรรัฐประศาสนศาสตร์มหาบัณฑิต สาขาวิชารัฐประศาสนศาสตร ภาคเรียนที่ 3/2568 โครงการจัดการเรียนการสอนระดับปริญญาตรีและระดับบัณฑิตศึกษา คณะศิลปศาสตร์และวิทยาศาสตร์ กิจกรรมที่ 2 (ผศ.ดร.ธิติรัตน์ เหล่าคมพฤฒาจารย์) | E13: 24750 | F13: =F12+D13-E13 -> 564000
A14: 515/69 | B14: 4 ก.ย. 69 | C14: ค่าตอบแทนการอาจารย์ที่ปรึกษา ระดับปริญญาโท หลักสูตรรัฐประศาสนศาสตร์มหาบัณฑิต สาขาวิชารัฐประศาสนศาสตร์ วันที่ โครงการจัดการเรียนการสอนระดับปริญญาตรีและระดับบัณฑิตศึกษา คณะศิลปศาสตร์และวิทยาศาสตร์ กิจกรรมที่ 2 (รศ.ดร.พิทักษ์พงศ์ กางการ) | E14: 4500 | F14: =F13+D14-E14 -> 559500
A15: 516/69 | B15: 4 ก.ย. 69 | C15: ค่าตอบแทนการอาจารย์ที่ปรึกษา ระดับปริญญาโท หลักสูตรรัฐประศาสนศาสตร์มหาบัณฑิต สาขาวิชารัฐประศาสนศาสตร์ จำนวน 9 เรื่อง โครงการจัดการเรียนการสอนระดับปริญญาตรีและระดับบัณฑิตศึกษา คณะศิลปศาสตร์และวิทยาศาสตร์ กิจกรรมที่ 2 (รศ.ดร.สมปอง สุวรรณภูมา) | E15: 40500 | F15: =F14+D15-E15 -> 519000
A16: 528/69 | B16: 15 ก.ย .69 | C16: ค่าตอบแทนการอาจารย์ที่ปรึกษา ระดับปริญญาโท หลักสูตรรัฐประศาสนศาสตร์มหาบัณฑิต สาขาวิชารัฐประศาสนศาสตร์ จำนวน 9 เรื่อง โครงการจัดการเรียนการสอนระดับปริญญาตรีและระดับบัณฑิตศึกษา คณะศิลปศาสตร์และวิทยาศาสตร์ กิจกรรมที่ 2 (ผศ.ดร.ธิติรัตน์ เหล่าพฤฒาจารย์) | E16: 36000 | F16: =F15+D16-E16 -> 483000
A17: รวมทั้งสิ้น | D17: =SUM(D4:D10) -> 743000 | E17: =SUM(E4:E16) -> 260000 | F17: =D17-E17 -> 483000
C19: *หมายเหตุ
C20: กันเงินค่าตอบแทนการสอน จำนวน 43,000 บาท

Sheet กิจกรรมที่ 6.3.
A1: กิจกรรมที่ 3 : จัดการเรียนการสอน หลักสูตรรัฐศาสตร์มหาบัณฑิต | G1: โครงการจัดการเรียนการสอน
C2: ระยะเวลาดำเนินโครงการ ไตรมาสที่ 1 - 4 (เดือน ต.ค. 67 - ก.ย. 68)
A3: ว/ด/ป/ | B3: ลำดับ | C3: รายการ | D3: รับ/อนุมัติ | E3: เบิก | F3: คงเหลือ
C4: กิจกรรมที่ 3 : จัดการเรียนการสอน หลักสูตรรัฐศาสตร์มหาบัณฑิต | D4: 569000 | F4: =D4-E4 -> 569000
A5: 23 เม.ย. 69 | B5: 156/69 | C5: ค่าตอบแทนการสอนระดับปริญญาโท หลักสูตรรัฐศาสตร์มหาบัณฑิต สาขาวิชารัฐศาสตร์ โครงการจัดการเรียนการสอนระดับปริญญาตรีและระดับบัณฑิตศึกษา คณะศิลปศาสตร์และวิทยาศาสตร์ กิจกรรมที่ 3 ภาคเรียนที่ 2/2568 อาจารย์ ดร.ธรรมรัตน์ โรมแพน | E5: 20400 | F5: =F4+D5-E5 -> 548600
A6: 23 เม.ย. 69 | B6: 157/69 | C6: ค่าตอบแทนการสอนระดับปริญญาเอก หลักสูตรรัฐศาสตร์มหาบัณฑิต สาขาวิชารัฐศาสตร์ โครงการจัดการเรียนการสอนระดับปริญญาตรีและระดับบัณฑิตศึกษา คณะศิลปศาสตร์และวิทยาศาสตร์ กิจกรรมที่ 3 ภาคเรียนที่ 2/2568 ผศ. ว่าที่พันตรี ดร.ณัฐดนัย แก้วโพนงาม | E6: 21600 | F6: =F5+D6-E6 -> 527000
A7: 23 เม.ย. 69 | B7: 158/69 | C7: ค่าตอบแทนการสอนระดับปริญญาโท หลักสูตรรัฐศาสตร์มหาบัณฑิต สาขาวิชารัฐศาสตร์ โครงการจัดการเรียนการสอนระดับปริญญาตรีและระดับบัณฑิตศึกษา คณะศิลปศาสตร์และวิทยาศาสตร์ กิจกรรมที่ 3 ภาคเรียนที่ 2/2568 ผศ. ว่าที่พันตรี ดร.ณัฐดนัย แก้วโพนงาม | E7: 20400 | F7: =F6+D7-E7 -> 506600 | G7: แก้ไขยอดจากเดิม 21,600 เป็น 20,400 บาท 5 พ.ค.69
A8: 7 พ.ค. 69 | B8: 186/69 | C8: ค่าตอบแทนการสอนระดับปริญญาโท หลักสูตรรัฐศาสตร์มหาบัณฑิต สาขาวิชารัฐศาสตร์ โครงการจัดการเรียนการสอนระดับปริญญาตรีและระดับบัณฑิตศึกษา คณะศิลปศาสตร์และวิทยาศาสตร์ กิจกรรมที่ 3 ภาคเรียนที่ 2/2568 อาจารย์ ดร.สามารถ สินทร | E8: 28800 | F8: =F7+D8-E8 -> 477800
A9: 18 มิ.ย.69 | B9: 253/69 | C9: ค่าตอบแทนการสอนระดับปริญญาโท หลักสูตรรัฐศาสตร์มหาบัณฑิต สาขาวิชารัฐศาสตร์ โครงการจัดการเรียนการสอนระดับปริญญาตรีและระดับบัณฑิตศึกษา คณะศิลปศาสตร์และวิทยาศาสตร์ กิจกรรมที่ 3 ภาคเรียนที่ 3/2568 อ.ดร.ธรรมรัตน์ โรมแพน | E9: 26400 | F9: =F8+D9-E9 -> 451400
A10: 18 มิ.ย.69 | B10: 254/69 | C10: ค่าตอบแทนการสอนระดับปริญญาโท หลักสูตรรัฐศาสตร์มหาบัณฑิต สาขาวิชารัฐศาสตร์ โครงการจัดการเรียนการสอนระดับปริญญาตรีและระดับบัณฑิตศึกษา คณะศิลปศาสตร์และวิทยาศาสตร์ กิจกรรมที่ 3 ภาคเรียนที่ 3/2568 ผศ.ว่าที่พันตรี ดร.ณัฐดนัย แก้วโพนงาม | E10: 22000 | F10: =F9+D10-E10 -> 429400
A11: 14 ก.ย.69 | B11: 519/69 | C11: ค่าตอบแทนการอาจารย์ที่ปรึกษา ระดับปริญญาโท หลักสูตรรัฐศาสตร์มหาบัณฑิต สาขาวิชารัฐศาสตร์ จำนวน 2 เรื่อง โครงการจัดการเรียนการสอนระดับปริญญาตรีและระดับบัณฑิตศึกษา คณะศิลปศาสตร์และวิทยาศาสตร์ กิจกรรมที่ 3 (อาจารย์ ดร.ชูเกียรติ ผลาผล) | E11: 9000 | F11: =F10+D11-E11 -> 420400
A12: 14 ก.ย.69 | B12: 520/69 | C12: ค่าตอบแทนการอาจารย์ที่ปรึกษา ระดับปริญญาโท หลักสูตรรัฐศาสตร์มหาบัณฑิต สาขาวิชารัฐศาสตร์ จำนวน 2 เรื่อง โครงการจัดการเรียนการสอนระดับปริญญาตรีและระดับบัณฑิตศึกษา คณะศิลปศาสตร์และวิทยาศาสตร์ กิจกรรมที่ 3 (อาจารย์ ดร.ธรรมรัตน์ โพธิสุวรรณปัญญา) | E12: 9000 | F12: =F11+D12-E12 -> 411400
A13: 14 ก.ย.69 | B13: 521/69 | C13: ค่าตอบแทนการอาจารย์ที่ปรึกษา ระดับปริญญาโท หลักสูตรรัฐศาสตร์มหาบัณฑิต สาขาวิชารัฐศาสตร์ จำนวน 3 เรื่อง โครงการจัดการเรียนการสอนระดับปริญญาตรีและระดับบัณฑิตศึกษา คณะศิลปศาสตร์และวิทยาศาสตร์ กิจกรรมที่ 3 (ผศ.ว่าที่พันตรี ดร.ณัฐดนัย แก้วโนงาม) | E13: 13500 | F13: =F12+D13-E13 -> 397900
F14: =F13+D14-E14 -> 397900
F15: =F14+D15-E15 -> 397900
A16: รวมทั้งสิ้น | D16: =SUM(D4:D10) -> 569000 | E16: =SUM(E4:E15) -> 171100 | F16: =D16-E16 -> 397900
C18: *หมายเหตุ
C19: กันเงินค่าตอบแทนการสอน จำนวน 45,450 บาท

Sheet กิจกรรมที่ 6.4.
A1: กิจกรรมที่ 4 : จัดการเรียนการสอน หลักสูตรรัฐศาสตรดุษฎีบัณฑิต | G1: โครงการจัดการเรียนการสอน
C2: ระยะเวลาดำเนินโครงการ ไตรมาสที่ 1 - 4 (เดือน ต.ค. 67 - ก.ย. 68)
A3: ว/ด/ป/ | B3: ลำดับ | C3: รายการ | D3: รับ/อนุมัติ | E3: เบิก | F3: คงเหลือ
C4: กิจกรรมที่ 4 : จัดการเรียนการสอน หลักสูตรรัฐศาสตรดุษฎีบัณฑิต | D4: 1137000 | F4: =D4-E4 -> 1137000
A5: 13/1/69 | B5: ร-113/69 | C5: ค่าตอบแทนอาจารย์ที่ปรึกษาวิทยานิพนธ์ระดับปริญญาเอก กลักสูตรรัฐศาสดุษฏีบัณฑิต สาขาวิชารัฐศาสตร์ ณัฐดนัย | E5: 30000 | F5: =F4+D5-E5 -> 1107000
A6: 13/1/69 | B6: ร-114/69 | C6: ค่าตอบแทนอาจารย์ที่ปรึกษาวิทยานิพนธ์ระดับปริญญาเอก กลักสูตรรัฐศาสดุษฏีบัณฑิต สาขาวิชารัฐศาสตร์ ธรรมรัตน์ | E6: 20000 | F6: =F5+D6-E6 -> 1087000
A7: 13/1/69 | B7: ร-115/69 | C7: ค่าตอบแทนอาจารย์ที่ปรึกษาวิทยานิพนธ์ระดับปริญญาเอก กลักสูตรรัฐศาสดุษฏีบัณฑิต สาขาวิชารัฐศาสตร์ ดร.ชูเกียรติ | E7: 10000 | F7: =F6+D7-E7 -> 1077000
A8: 13/1/69 | B8: ร-116/69 | C8: ค่าตอบแทนการสอน ระดับปริญญาเอก หลักสูตรรัฐศาสตรดุษฏีบัณฑิต สาขาวิชารัฐศาสตร์ อ.ดร.สามารถ สินทร | E8: 54400 | F8: =F7+D8-E8 -> 1022600
A9: 13/1/69 | B9: ร-117/69 | C9: ค่าตอบแทนการสอน ระดับปริญญาเอก หลักสูตรรัฐศาสตรดุษฏีบัณฑิต สาขาวิชารัฐศาสตร์ อ.ดร.เกษกนก | E9: 54400 | F9: =F8+D9-E9 -> 968200
A10: 13/1/69 | B10: ร-118/69 | C10: ค่าตอบแทนการสอน ระดับปริญญาเอก หลักสูตรรัฐศาสตรดุษฏีบัณฑิต สาขาวิชารัฐศาสตร์ อ.ดร.สามารถ สินทร | E10: 54400 | F10: =F9+D10-E10 -> 913800
A11: 7 พ.ค. 69 | B11: 187/69 | C11: ค่าตอบแทนอาจารย์ที่ปรึกษาวิทยานิพนธ์ ระดับปริญญาเอก หลักสูตรรัฐศาสตรดุษฎีบัณฑิต สาขาวิชารัฐศาสตร์ โครงการจัดการเรียนการสอนระดับปริญญาตรีและระดับบัณฑิตศึกษา คณะศิลปศาสตร์และวิทยาศาสตร์ กิจกรรมที่ 4 อาจารย์ ดร.ชูเกียรติ ผลาผล | E11: 15000 | F11: =F10+D11-E11 -> 898800
A12: 7 พ.ค. 69 | B12: 188/69 | C12: ค่าตอบแทนอาจารย์ที่ปรึกษาวิทยานิพนธ์ ระดับปริญญาเอก หลักสูตรรัฐศาสตรดุษฎีบัณฑิต สาขาวิชารัฐศาสตร์ โครงการจัดการเรียนการสอนระดับปริญญาตรีและระดับบัณฑิตศึกษา คณะศิลปศาสตร์และวิทยาศาสตร์ กิจกรรมที่ 4 ผศ.ว่าที่พันตรี ดร.ณัฐดนัย แก้วโพนงาม | E12: 30000 | F12: =F11+D12-E12 -> 868800
A13: 7 พ.ค. 69 | B13: 189/69 | C13: ค่าตอบแทนอาจารย์ที่ปรึกษาวิทยานิพนธ์ ระดับปริญญาเอก หลักสูตรรัฐศาสตรดุษฎีบัณฑิต สาขาวิชารัฐศาสตร์ โครงการจัดการเรียนการสอนระดับปริญญาตรีและระดับบัณฑิตศึกษา คณะศิลปศาสตร์และวิทยาศาสตร์ กิจกรรมที่ 4 อาจารย์ ดร.ธรรมรัตน์ โรมแพม | E13: 20000 | F13: =F12+D13-E13 -> 848800
A14: 7 พ.ค. 69 | B14: 190/69 | C14: ค่าตอบแทนอาจารย์ที่ปรึกษาวิทยานิพนธ์ ระดับปริญญาเอก หลักสูตรรัฐศาสตรดุษฎีบัณฑิต สาขาวิชารัฐศาสตร์ โครงการจัดการเรียนการสอนระดับปริญญาตรีและระดับบัณฑิตศึกษา คณะศิลปศาสตร์และวิทยาศาสตร์ กิจกรรมที่ 4 อาจารย์ ดร.ชูเกียรติ ผลาผล | E14: 10000 | F14: =F13+D14-E14 -> 838800
A15: 7 พ.ค. 69 | B15: 191/69 | C15: ค่าตอบแทนอาจารย์ที่ปรึกษาวิทยานิพนธ์ ระดับปริญญาเอก หลักสูตรรัฐศาสตรดุษฎีบัณฑิต สาขาวิชารัฐศาสตร์ โครงการจัดการเรียนการสอนระดับปริญญาตรีและระดับบัณฑิตศึกษา คณะศิลปศาสตร์และวิทยาศาสตร์ กิจกรรมที่ 4 ผศ.ว่าที่พันตรี ดร.ณัฐดนัย แก้วโพนงาม | E15: 40000 | F15: =F14+D15-E15 -> 798800
A16: 7 พ.ค. 69 | B16: 192/69 | C16: ค่าตอบแทนอาจารย์ที่ปรึกษาวิทยานิพนธ์ ระดับปริญญาเอก หลักสูตรรัฐศาสตรดุษฎีบัณฑิต สาขาวิชารัฐศาสตร์ โครงการจัดการเรียนการสอนระดับปริญญาตรีและระดับบัณฑิตศึกษา คณะศิลปศาสตร์และวิทยาศาสตร์ กิจกรรมที่ 4 อาจารย์ ดร.ธรรมรัตน์ โรมแพม | E16: 25000 | F16: =F15+D16-E16 -> 773800
... A29: 14 ก.ย. 69 | B29: 525/69 | C29: ค่าตอบแทนการอาจารย์ที่ปรึกษาวิทยานิพนธ์หลัก ระดับปริญญาเอก หลักสูตรรัฐศาสตร์ดุษฎีบัณฑิต สาขาวิชารัฐศาสตร์ จำนวน 1 เรื่อง โครงการจัดการเรียนการสอนระดับปริญญาตรีและระดับบัณฑิตศึกษา คณะศิลปศาสตร์และวิทยาศาสตร์ กิจกรรมที่ 4 (ผศ.ว่าที่พันตรี ดร.ณัฐดนัย แก้วโนงาม) | E29: 15000 | F29: =F28+D29-E29 -> 528050
A30: 14 ก.ย. 69 | F30: =F29+D30-E30 -> 528050
A31: รวมทั้งสิ้น | D31: =SUM(D4:D10) -> 1137000 | E31: =SUM(E4:E30) -> 608950 | F31: =D31-E31 -> 528050
C33: *หมายเหตุ | E33: เงินกัน | F33: คงเหลือ
C34: กันเงินค่าตอบแทนการสอน จำนวน 60,000 บาท | E34: 60000
C35: กันเงินค่าค่าสอนปริญญาตรี จำนวน 66,000 บาท | E35: 66000
E36: =SUM(E34:E35) -> 126000 | F36: =F31-E36 -> 402050
D38: เบิกกศ.ปช
D39: ขอใช้ | E39: ใช้ไป | F39: คงเหลือ
D40: 77750 | E40: =E23 -> 11750 | F40: =D40-E40 -> 66000

Sheet กิจกรรมที่ 6.5.
A1: กิจกรรมที่ 5 : จัดการเรียนการสอน ระดับปริญญาตรี | G1: โครงการจัดการเรียนการสอน
C2: ระยะเวลาดำเนินโครงการ ไตรมาสที่ 1 - 4 (เดือน ต.ค. 67 - ก.ย. 68)
A3: ว/ด/ป/ | B3: ลำดับ | C3: รายการ | D3: รับ/อนุมัติ | E3: เบิก | F3: คงเหลือ
C4: กิจกรรมที่ 5 : จัดการเรียนการสอน ระดับปริญญาตรี | D4: 178500 | F4: =D4-E4 -> 178500
A5: 15 ม.ค. 69 | B5: 033/69 | C5: ค่าตอบแทนการสอนระดับปริญญาตรี ภาคเรียนที่ 1/2568 ภาค กศ.ปช. วิชา กฎหมายปกครอง รหัส 3012115 โครงการจัดการเรียนการสอนระดับปริญญาตรีและระดับบัณฑิตศึกษาฯ กิจกรรมที่ 5 ผศ.ดร.ฉัตรณรงค์ศักดิ์ สุธรรมดี | E5: 9000 | F5: =F4+D5-E5 -> 169500
B6: 034/69 | C6: ค่าตอบแทนการสอนระดับปริญญาตรี ภาคเรียนที่ 1/2568 ภาค กศ.ปช. วิชา ความรู้เบื้องต้นเกี่ยวกับรัฐศาสตร์ รหัส 3012102 โครงการจัดการเรียนการสอนระดับปริญญาตรีและระดับบัณฑิตศึกษาฯ กิจกรรมที่ 5 อ.ดร.ดาศรินทร์พัชร์ สุธรรมดี | E6: 9000 | F6: =F5+D6-E6 -> 160500
B7: 035/69 | C7: ค่าตอบแทนการสอนระดับปริญญาตรี ภาคเรียนที่ 1/2568 ภาค กศ.ปช. วิชา ความรู้เบื้องต้นเกี่ยวกับรัฐประศาสนศาสตร์ รหัส 3012101 โครงการจัดการเรียนการสอนระดับปริญญาตรีและระดับบัณฑิตศึกษาฯ กิจกรรมที่ 5 อาจารย์ อัญชิรญา จันทรปิฎก | E7: 9000 | F7: =F6+D7-E7 -> 151500
A8: 23 มี.ค. 69 | B8: 108/69 | C8: ค่าตอบแทนการสอนระดับปริญญาตรี ภาคการศึกษาที่ 2/2568 (กศ.ปช.) วิชาการเป็นผู้ประกอบการสมัยใหม่ รหัส 4012218 และวิชาธุรกิจสตาร์ทอัพ รหัส 4012209 สาขาวิชาการจัดการ โครงการจัดการเรียนการสอนระดับปริญญาตรีและระดับบัณฑิตศึกษาฯ กิจกรรมที่ 5 ผศ.หทัยกาญจน์ ทองศรีสุข | E8: 31500 | F8: =F7+D8-E8 -> 120000
A9: 9 เม.ย. 69 | B9: 139/69 | C9: ค่าตอบแทนการสอนระดับปริญญาตรี ภาคเรียนที่ 2/2568 ภาคการศึกษาเพื่อปวงชน (กศ.ปช) วิชา การเมืองการปกครองไทย รหัส 3012103 โครงการจัดการเรียนการสอนระดับปริญญาตรีและระดับบัณฑิตศึกษาฯ กิจกรรมที่ 5 อ.ดร.ณัฐปราย์ ชัยสินคุณานนต์ | E9: 9000 | F9: =F8+D9-E9 -> 111000
A10: 9 เม.ย. 69 | B10: 140/69 | C10: ค่าตอบแทนการสอนระดับปริญญาตรี ภาคเรียนที่ 2/2568 ภาคการศึกษาเพื่อปวงชน (กศ.ปช) วิชา ความรู้เบื้องต้นเกี่ยวกับกฎหมาย รหัส 3012105 โครงการจัดการเรียนการสอนระดับปริญญาตรีและระดับบัณฑิตศึกษาฯ กิจกรรมที่ 5 อ.ดร.ณัฐปราย์ ชัยสินคุณานนต์ | E10: 11250 | F10: =F9+D10-E10 -> 99750
A11: 7 พ.ค. 69 | B11: 199/69 | C11: ค่าตอบแทนการสอนระดับปริญญาตรี ภาคเรียนที่ 2/2568 ภาคการศึกษาเพื่อปวงชน (กศ.ปช) วิชา นวัตกรรมการจัดการทางการเงิน รหัส 4012208 โครงการจัดการเรียนการสอนระดับปริญญาตรีและระดับบัณฑิตศึกษาฯ กิจกรรมที่ 5 นางสาวรัศมีเพ็ญ นาครินทร์ | E11: 13500 | F11: =F10+D11-E11 -> 86250
A12: 15 มิ.ย. 69 | B12: 240/69 | C12: ค่าตอบแทนการสอนระดับปริญญาตรี ภาคเรียนที่ 3/2568 ภาคการศึกษาเพื่อปวงชน (กศ.ปช) วิชา สมันาทางการจัดการ รหัสวิชา 4012211 โครงการจัดการเรียนการสอนระดับปริญญาตรีและระดับบัณฑิตศึกษาฯ กิจกรรมที่ 5 อาจารย์สุภร วรรณสิงห์ | E12: 18000 | F12: =F11+D12-E12 -> 68250
A13: 16 มิ.ย. 69 | B13: 248/69 | C13: ค่าตอบแทนการสอนระดับปริญญาตรี ภาคเรียนที่ 3/2568 ภาคการศึกษาเพื่อปวงชน (กศ.ปช) วิชา การจัดการการตลาด รหัสวิชา 4012206 โครงการจัดการเรียนการสอนระดับปริญญาตรีและระดับบัณฑิตศึกษาฯ กิจกรรมที่ 5 ผศ.หทัยกาญจน์ ทองศรีสุข | E13: 18000 | F13: =F12+D13-E13 -> 50250
A14: 24 มิ.ย. 69 | B14: 266/69 | C14: ค่าตอบแทนการสอนระดับปริญญาตรี ภาคเรียนที่ 3/2568 ภาคการศึกษาเพื่อปวงชน (กศ.ปช) วิชา การวิเคราะห์งบการเงินและรายงานทางการเงิน รหัสวิชา 4012219 โครงการจัดการเรียนการสอนระดับปริญญาตรีและระดับบัณฑิตศึกษาฯ กิจกรรมที่ 5 อาจารย์สุนันทา สุภพล | E14: 10000 | F14: =F13+D14-E14 -> 40250
A15: 6 ก.ค. 69 | B15: 284/69 | C15: ค่าตอบแทนการสอนระดับปริญญาตรี ภาคเรียนที่ 2/2568 ภาคการศึกษาเพื่อปวงชน (กศ.ปช) วิชา พฤติกรรมผู้บริโภคในยุคดิจิทัล รหัสวิชา 4012216 โครงการจัดการเรียนการสอนระดับปริญญาตรีและระดับบัณฑิตศึกษาฯ กิจกรรมที่ 5 อาจารย์เสกศักดิ์ ปราบพาลา | E15: 13500 | F15: =F14+D15-E15 -> 26750
A16: 9 ก.ค. 69 | B16: 296/69 | C16: ค่าตอบแทนการสอนระดับปริญญาตรี ภาคเรียนที่ 3/2568 ภาคการศึกษาเพื่อปวงชน (กศ.ปช) วิชา กฎหมายรัฐธรรมนูญ รหัสวิชา 3012109 โครงการจัดการเรียนการสอนระดับปริญญาตรีและระดับบัณฑิตศึกษาฯ กิจกรรมที่ 5 ผศ.ดร.ฉัตรณรงค์ศักดิ์ สุธรรมดี | E16: 10000 | F16: =F15+D16-E16 -> 16750
A17: 23 ก.ค. 69 | B17: 325/69 | C17: ค่าตอบแทนการสอนระดับปริญญาตรี ภาคเรียนที่ 3/2568 ภาคการศึกษาเพื่อปวงชน (กศ.ปช) วิชา องค์การและการจัดการสมัยใหม่ รหัสวิชา 3012124 โครงการจัดการเรียนการสอนระดับปริญญาตรีและระดับบัณฑิตศึกษาฯ กิจกรรมที่ 5 อ.ดร.พรหมพรปวีณ์ ใชยเรื่อง | E17: 12000 | F17: =F16+D17-E17 -> 4750
A18: 29 ส.ค. 69 | B18: 404/69 | C18: ค่าตอบแทนการสอนระดับปริญญาตรี ภาคเรียนที่ 3/2568 ภาคการศึกษาเพื่อปวงชน (กศ.ปช) วิชาการจัดการเชิงกลยุทธ์ รหัสวิชา 4002111 โครงการจัดการเรียนการสอนระดับปริญญาตรีและระดับบัณฑิตศึกษาฯ กิจกรรมที่ 5 จำนวน 4750 บาท และกิจกรรมที่ 4 จำนวน 11,750 บาท รวมทั้งสิน 16,500 บาท อาจารย์ ดร.รัศมีเพ็ญ นาครินทร์ | E18: 4750 | F18: =F17+D18-E18 -> 0
A19: รวมทั้งสิ้น | D19: =SUM(D4:D10) -> 178500 | E19: =SUM(E4:E18) -> 178500 | F19: =D19-E19 -> 0
C21: *หมายเหตุ

Sheet 7.โครงการนิเทศ
A1: โครงการนิเทศนักศึกษาฝึกประสบการณ์วิชาชีพ หรือสหกิจศึกษา คณะศิลปศาสตร์และวิทยาศาสตร์ ประจำปีงบประมาณ 2569 | F1: หน้าหลัก
A2: ระยะเวลาดำเนินโครงการ ในไตรมาสที่ 1 - 4 ( ต.ค. 68 - ก.ย. 69)
A3: รหัสโครงการ | B3: ชื่อโครงการ | C3: งบประมาณ | D3: เบิก-จ่าย | E3: คงเหลือ
B4: ยอดเงินทั้งหมด | C4: 625300 | E4: =C4-D4 -> 625300
A5: กิจกรรมที่ 7.1 | B5: กิจกรรมที่ 1 : นิเทศนักศึกษาฝึกประสบการณ์วิชาชีพ หรือสหกิจศึกษา | C5: ='กิจกรรมที่ 7.1'!D62 -> 537540 | D5: ='กิจกรรมที่ 7.1'!E62 -> 491490 | E5: =C5-D5 -> 46050
A6: กิจกรรมที่ 7.2 | B6: กิจกรรมที่ 2 : นิเทศนักศึกษาฝึกประสบการณ์วิชาชีพ ฝึกงาน หรือสหกิจศึกษา หลักสูตรวิศวกรรมศาสตรบัณฑิต | C6: ='กิจกรรมที่ 7.2'!D18 -> 87760 | D6: ='กิจกรรมที่ 7.2'!E18 -> 84108 | E6: =C6-D6 -> 3652
A7: รวมทั้งสิ้น | C7: =SUM(C5:C6) -> 625300 | D7: =SUM(D5:D6) -> 575598 | E7: =C7-D7 -> 49702
A9: ผู้รับผิดชอบโครงการ
B10: กิจกรรมที่ 1 | C10: =C5 -> 537540 | D10: =D5+33600 -> 525090 | E10: =C10-D10 -> 12450
B11: กิจกรรมที่ 2 | C11: =C6 -> 87760 | D11: =D6 -> 84108 | E11: =C11-D11 -> 3652
E12: =SUM(E10:E11) -> 16102

Sheet กิจกรรมที่ 7.1
A1: กิจกรรมที่ 1 : นิเทศนักศึกษาฝึกประสบการณ์วิชาชีพ หรือสหกิจศึกษา | G1: โครงการนิเทศ
C2: ระยะเวลาดำเนินโครงการ ในไตรมาสที่ 1 - 4 ( ต.ค.68 - ก.ย. 69)
A3: ว/ด/ป/ | B3: ลำดับ | C3: รายการ | D3: รับ/อนุมัติ | E3: เบิก | F3: คงเหลือ
C4: กิจกรรมที่ 1 : นิเทศนักศึกษาฝึกประสบการณ์วิชาชีพ หรือสหกิจศึกษา | D4: 537540 | F4: =D4-E4 -> 537540
A5: 21 ม.ค. 69 | B5: 040/69 | C5: ค่านิเทศ อาจารย์สุภร วรรณสิงห์ วิชาเอกการจัดการธุรกิจการค้าสมัยใหม่ รหัสวิชา 4004504 สหกิจศึกษาด้านการจัดการธุรกิจการค้าสมัยใหม่ จำนวน 4 คน 2 ครั้ง โครงการนิเทศฝึกประสบการวืชาชีพ ฯกิจกรรมที่ 1 | E5: 3200 | F5: =F4-E5 -> 534340
A6: 10 ก.พ.69 | B6: 047/69 | C6: ค่านิเทศ อาจารย์ ดร.วาสนา เจริญวัย วิชาเอกการจัดการธุรกิจการค้าสมัยใหม่ รหัสวิชา 4004504 สหกิจศึกษาด้านการจัดการธุรกิจการค้าสมัยใหม่ จำนวน 4 คน 2 ครั้ง โครงการนิเทศฝึกประสบการวืชาชีพ ฯกิจกรรมที่ 1 | E6: 3200 | F6: =F5-E6 -> 531140
A7: 13 ก.พ. 69 | B7: 050/69 | C7: ค่านิเทศ ผศ.ดร.เกศสุดา โภคานิตย์ สาขารัฐศาสตร์ รายวิชาฝึกประสบการณ์วิชาชีพทางรัฐศาสตร์ รหัส 3022403 จำนวน 4 คน 2 ครั้ง โครงการนิเทศฝึกประสบการวืชาชีพ ฯกิจกรรมที่ 1 | E7: 3200 | F7: =F6-E7 -> 527940
A8: 25 ก.พ. 69 | B8: 054/69 | C8: ค่านิเทศ อาจารย์ ดร.ธนิกานต์ ศรีจันทร์ สาขาวิชารัฐศาสตร์ รหัสวิชา 3022403รายวิชาฝึกประสบการณ์วิชาชีพทางรัฐศาสตร์ จำนวน 5 คน 2 ครั้ง โครงการนิเทศฝึกประสบการวืชาชีพ ฯกิจกรรมที่ 1 | E8: 4000 | F8: =F7-E8 -> 523940
A9: 25 ก.พ. 69 | B9: 055/69 | C9: ค่านิเทศ ผศ.ดร.อนุสรณ์ พัฒนศานติ์ สาขาวิชารัฐศาสตร์ รหัสวิชา 3022403รายวิชาฝึกประสบการณ์วิชาชีพทางรัฐศาสตร์ จำนวน 4 คน 2 ครั้ง โครงการนิเทศฝึกประสบการวืชาชีพ ฯกิจกรรมที่ 1 | E9: 3200 | F9: =F8-E9 -> 520740
A10: 25 ก.พ. 69 | B10: 056/69 | C10: ค่านิเทศ ดร.ณัฐปราย์ ชัยสินคุณานนต์ สาขาวิชารัฐประศาสนศาสตร์ รหัสวิชา 3012402 รายวิชาฝึกประสบการณ์วิชาชีพสหกิจศึกษา จำนวน 4 คน 2 ครั้ง โครงการนิเทศฝึกประสบการวืชาชีพ ฯกิจกรรมที่ 1 | E10: 3200 | F10: =F9-E10 -> 517540
A11: 25 ก.พ. 69 | B11: 059/69 | C11: ค่านิเทศ อาจารย์ฤทธิชัย ผานาค สาขาวิชาวิทยาการคอมพิวเตอร์ รหัสวิชา 1138041 รายวิชาการฝึกงานคอมพิวเตอร์ จำนวน 4 คน 2 ครั้ง โครงการนิเทศฝึกประสบการวืชาชีพ ฯกิจกรรมที่ 1 | E11: 3200 | F11: =F10-E11 -> 514340
A12: 27 ก.พ.69 | B12: 064/69 | C12: ค่านิเทศ ผศ.หทัยกาญจน์ ทองศรีสุข สาขาวิชาบริหารธุรกิจ วิชาเอกการจัดการ (กศ.ปช.) รหัสวิชา 4004503 รายวิชาสหกิจศึกษา 1 และสหกิจศึกษา 2 จำนวน 4 คน 2 ครั้ง โครงการนิเทศฝึกประสบการวืชาชีพ ฯกิจกรรมที่ 1 | E12: 3200 | F12: =F11-E12 -> 511140
A13: 27 ก.พ.69 | B13: 065/69 | C13: ค่านิเทศ ผศ.หทัยกาญจน์ ทองศรีสุข สาขาวิชาบริหารธุรกิจ วิชาเอกการจัดการ รหัสวิชา 4004503 รายวิชาสหกิจศึกษา 2 จำนวน 8 คน 2 ครั้ง โครงการนิเทศฝึกประสบการวืชาชีพ ฯกิจกรรมที่ 1 | E13: 6400 | F13: =F12-E13 -> 504740
A14: 068/69 | B14: 27 ก.พ.69 | C14: ค่านิเทศ ดร.ดาศรินทร์พัชร์ สุธรรมดี สาขาวิชารัฐศาสตร์ รหัสวิชา 3022403 รายวิชาฝึกประสบการณ์วิชาชีพทางรัฐศาสตร์ จำนวน 5 คน 2 ครั้ง โครงการนิเทศฝึกประสบการวืชาชีพ ฯกิจกรรมที่ 1 | E14: 4000 | F14: =F13-E14 -> 500740
A15: 069/69 | B15: 27 ก.พ.69 | C15: ค่านิเทศ ผศ.ดร.เทอดศักดิ์ ไป่จันทึก สาขาวิชารัฐศาสตร์ รหัสวิชา 3022403 รายวิชาฝึกประสบการณ์วิชาชีพทางรัฐศาสตร์ จำนวน 4 คน 2 ครั้ง โครงการนิเทศฝึกประสบการวืชาชีพ ฯกิจกรรมที่ 1 | E15: 3200 | F15: =F14-E15 -> 497540
A16: 072/69 | B16: 2 มี.ค.69 | C16: ค่านิเทศ ผศ.ดร.ฉัตรณรงค์ศักดิ์ สุธรรมดี สาขาวิชารัฐประศาสนศาสตร์ รหัสวิชา 3012404 รายวิชาฝึกประสบการณ์วิชาชีพสหกิจศึกษา จำนวน 4 คน 2 ครั้ง โครงการนิเทศฝึกประสบการวืชาชีพ ฯกิจกรรมที่ 1 | E16: 3200 | F16: =F15-E16 -> 494340
... A61: 531/69 | B61: 15 ก.ย. 69 | C61: จัดซื้อวัสดุกิจกรรมที่ 1 จำนวน 3 รายการ จำนวน 160,000 บาท กิจกรรมที่ 2 จำนวน 3 รายการ จำนวน 52,000 บาท โครงการนิเทศนักศึกษาฝึกประสบการณ์วิชาชีพ หรือสหกิจศึกษา คณะศิลปศาสตร์และวิทยาศาสตร์ ประจำปีงบประมาณ 2569 (อัญชรี ยูทิลิตี้) อาจารย์ ดร.รัชวุธ สุทธิ | E61: 160000 | F61: =F60-E61 -> 46050
A62: รวมทั้งสิ้น | D62: =SUM(D4:D5) -> 537540 | E62: =SUM(E5:E61) -> 491490 | F62: =D62-E62 -> 46050
C64: *หมายเหตุ
C65: กันเงินค่านิเทศ เทอม 1/2569 จำนวน 33,600 บาท | E65: =F62-33600 -> 12450

Sheet กิจกรรมที่ 7.2
A1: กิจกรรมที่ 2 : นิเทศนักศึกษาฝึกประสบการณ์วิชาชีพ ฝึกงาน หรือสหกิจศึกษา หลักสูตรวิศวกรรมศาสตรบัณฑิต | G1: โครงการนิเทศ
C2: ระยะเวลาดำเนินโครงการ ในไตรมาสที่ 1 - 4 ( ต.ค.68 - ก.ย. 69)
A3: ว/ด/ป/ | B3: ลำดับ | C3: รายการ | D3: รับ/อนุมัติ | E3: เบิก | F3: คงเหลือ
C4: กิจกรรมที่ 2 : นิเทศนักศึกษาฝึกประสบการณ์วิชาชีพ ฝึกงาน หรือสหกิจศึกษา หลักสูตรวิศวกรรมศาสตรบัณฑิต | D4: 87760 | F4: =D4-E4 -> 87760
A5: 4 มี.ค. 69 | B5: 073/69 | C5: ค่าใช้จ่ายเดินทางไปราชการ ระหว่างวันที่ 2 กุมภาพันธ์ 2569 เพื่อไปนิเทศนักศึกษาสหกิจศึกษา หลักสูตรวิศวกรรมศาสตรบัณฑิต สาขาวิศวกรรมเครื่องกล ณ เอเชียทีค เดอะริเวอร์ฟรอนท์ เลขที่ 2194 ถนนเจริญกรุง แขวงวัดพระยาไกร เขตบางคอแหลม, กรุงเทพมหานคร 10120 โครงการนิเทศฝึกประสบการวืชาชีพ ฯกิจกรรมที่ 2 อาจารย์ ผศ ดร.พงษ์ภูไท อุดมอริยทรัพย์ (ค่าเบี้ยเลี้ยง/ค่าน้ำมันเชื้อเพลิง) | E5: 3080 | F5: =F4-E5 -> 84680
A6: 4 ส.ค. 69 | B6: 337/69 | C6: ค่าใช้จ่ายเดินทางไปราชการเพื่อนิทศนักศึกษาสหกิจศึกษา หลักสูตรวิศวกรรมศาสตรบัณฑิต สาขาวิชาวิศวกรรมอุตสาหการและโลจิสติกส์ ในพื้นที่จังหวัดปทุมธานี จังหลัดชลบุรี และจังหวัดสมุทรปราการ ระหว่างวันที่ 1 - 3 กรกฎาคม 2569 โครงการนิเทศนักศึกษาฝึกประสบการณ์วิชาชีพ หรือสหกิจศึกษา คณะศิลปศาสตร์และวิทยาศาสตร์ ประจำปีงบประมาณ 2569 กิจกรรมที่ 2 (ค่าเบี้ยเลี้ยง/ค่าน้ำมันเชื้อเพลิง/ค่าที่พักเหมาจ่าย) อาจารย์วราภรณ์ จันทร์เวียง | E6: 8340 | F6: =F5-E6 -> 76340
A7: 5 ส.ค. 69 | B7: อว 0646.02/1395 ลงวันที่ 5 ส.ค 69 | C7: บันทึกข้อความ เรื่อง ขออนุญาตเดินทางไปราชการ โดยอาจารย์ชยารัก ธานี ติขะกุล พร้อมคณะ เพื่อนิเทศนักศึกษาสหกิจศึกษา หลักสูตรวิศวกรรมศาสตรบัณฑิต สาขาวิชาวิศวกรรมการผลิตและระบบอัตโนมัติ ในวันที่ 17 สิงหาคม 2569 ณ บริษัท เนเด็ด (ประเทศไทย) จำกัด ตำบลหนองระเวียง อำเภอเมืองนครราชสีมา จังหวัดนครราชสีมา | D7: 1944 | F7: =F6-E7 -> 76340
A8: 5 ส.ค. 69 | B8: อว 0646.02/1396 ลงวันที่ 5 ส.ค 69 | C8: บันทึกข้อความ เรื่อง ขออนุญาตเดินทางไปราชการ โดยอาจารย์ชยารัก ธานี ติขะกุล พร้อมคณะ เพื่อนิเทศนักศึกษาสหกิจศึกษา หลักสูตรวิศวกรรมศาสตรบัณฑิต สาขาวิชาวิศวกรรมการผลิตและระบบอัตโนมัติ ในวันที่ 26 - 28 สิงหาคม 2569 ณ บริษัท ทีม ซีเอฟ พรีซิชั่น จำกัด จ.นนทบุรี บริษัท เอฟเอ็มพี กรุ๊ป (ประเทศไทย) จำกัด จ.ระยอง และบริษัท พี่.เจชลบุรี พาราวู้ด จำกัด จ.ชลบุรี | D8: 8352 | F8: =F7-E8 -> 76340
A9: 13 ส.ค. 69 | B9: อว 0646.02/1469 ลงวันที่ 13 ส.ค 69 | C9: บันทึกข้อความ เรื่อง ขออนุญาตเดินทางไปราชการ โดยอาจารย์วราภรณ์ จันทร์เวียง พร้อมคณะ เพื่อนิเทศนักศึกษาสหกิจศึกษา หลักสูตรวิศวกรรมศาสตรบัณฑิต สาขาวิชาวิศวกรรมอุตสาหรการและโลจิสติกส์ ในวันที่ 18 - 20 สิงหาคม 2569 ในพื้นที่จังหวัดสมุทรปราการ และจังหวัดชลบุรี | D9: 8704 | F9: =F8-E9 -> 76340
A10: 13 ส.ค. 69 | B10: อว 0646.02/1470 ลงวันที่ 13 ส.ค 69 | C10: บันทึกข้อความ เรื่อง ขออนุญาตเดินทางไปราชการ โดยอาจารย์ ดร.รัชวุธ สุทธิ พร้อมคณะ เพื่อนิเทศนักศึกษาสหกิจศึกษา หลักสูตรวิศวกรรมศาสตรบัณฑิต สาขาวิชาวิศวกรรมอุตสาหรการและโลจิสติกส์ ในวันที่ 24 สิงหาคม 2569 ณ บริษัท แทร็กซ์ อินเตอร์เทรด จำกัด (สาขาชัยภูมิ) อำเภอจัตุรัส จังหวัดชัยภูมิ | D10: 1088 | F10: =F9-E10 -> 76340
A11: 13 ส.ค. 69 | B11: อว 0646.02/1471 ลงวันที่ 13 ส.ค 69 | C11: บันทึกข้อความ เรื่อง ขออนุญาตเดินทางไปราชการ โดยอาจารย์ ดร.รัชวุธ สุทธิ พร้อมคณะ เพื่อนิเทศนักศึกษาสหกิจศึกษา หลักสูตรวิศวกรรมศาสตรบัณฑิต สาขาวิชาวิศวกรรมอุตสาหรการและโลจิสติกส์ ในวันที่ 26 สิงหาคม 2569 ณ บริษัท ไฮ - เทค ชัยภูมิ แอพราเรล (2011) จำกัด อำเภอเมืองชัยภูมิ จังหวัดชัยภูมิ | D11: 120 | F11: =F10-E11 -> 76340
A12: 1 ก.ย. 69 | B12: 408/69 | C12: ค่าใช้จ่ายเดินทางไปราชการเพื่อนิเทศนักศึกษาสหกิจศึกษา หลักสูตรวิศวกรรมศาสตรบัณฑิต สาขาวิศวกรรมการผลิตและระบบอัตโนมัติ ณ บริษัท ทีม ซีเอฟ พรีซิชั่น จำกัด ตำบลบางตะไนย์ อำเภอปากเกร็ด จังหวัดนนทบุรี บริษัท เอฟเอ็มพี กรุ๊ป (ประเทศไทย)จำกัด ตำบลปลวกแดง อำเภอปลวกแดง จังหวัดระยอง และบริษํท พี.เจ ชลบุรี พาราวู้ด จำกัด ตำบลคลองกิ่ว อำเภอบ้านบึง จังหวัดชลบุรี ในระหวางวันที่ 26 - 28 สิงหาคม 2569 โครงการนิเทศนักศึกษาฝึกประสบการณ์วิชาชีพ หรือสหกิจศึกษา คณะศิลปศาสตร์และวิทยาศาสตร์ ประจำปีงบประมาณ 2569 กิจกรรมที่ 2 (ค่าที่พัก/ค่าเบี้ยเลี้ยง/ค่าน้ำมันเชื้อเพลิง) อาจารย์ชยารัก ธานี ติขะกุล | E12: 8352 | F12: =F11-E12 -> 67988
A13: 3 ก.ย. 69 | B13: 436/69 | C13: ค่าใช้จ่ายเดินทางไปราชการเพื่อนิเทศนักศึกษาสหกิจศึกษา หลักสูตรวิศวกรรมศาสตรบัณฑิต สาขาวิชาวิศวกรรมการผลิตและระบบอัตโนมัติ ในวันที่ 17 สิงหาคม 2569 ณ บริษัท เนเด็ด (ประเทศไทย) จำกัด ตำบลหนองระเวียง อำเภอเมืองนครราชสีมา จังหวัดนครราชสีมา (ค่าน้ำมันเชื้อเพลิง/ค่าเบี้ยเลี้ยง) อาจารย์ ดร.วิภารัตน์ นิสาภัย | E13: 1784 | F13: =F12-E13 -> 66204
A14: 3ก.ย. 69 | B14: 452/69 | C14: ค่าใช้จ่ายเดินทางไปราชการ เพื่อนิเทศนักศึกษาสหกิจศึกษา หลักสูตรวิศวกรรมศาสตรบัณฑิต สาขาวิชาวิศวกรรมอุตสาหรการและโลจิสติกส์ ในวันที่ 24 สิงหาคม 2569 ณ บริษัท แทร็กซ์ อินเตอร์เทรด จำกัด (สาขาชัยภูมิ) อำเภอจัตุรัส จังหวัดชัยภูมิ โครงการนิเทศนักศึกษาฝึกประสบการณ์วิชาชีพ หรือสหกิจศึกษา คณะศิลปศาสตร์และวิทยาศาสตร์ ประจำปีงบประมาณ 2569 กิจกรรมที่ 2 (ค่าเบี้ยเลี้ยง/ค่าน้ำมันเชื้อเพลิง) อาจารย์กมลรักษ์ แก้งคำ | E14: 728 | F14: =F13-E14 -> 65476
A15: 3 ก.ย. 69 | B15: 453/69 | C15: ค่าใช้จ่ายเดินทางไปราชการเพื่อนิเทศนักศึกษาสหกิจศึกษา หลักสูตรวิศวกรรมศาสตรบัณฑิต สาขาวิชาวิศวกรรมอุตสาหการและโลจิสติกส์ ในวันที่ 26 สิงหาคม 2569 ณ บริษัท ไฮ - เทค ชัยภูมิ แอพราเรล (2011) จำกัด อำเภอเมืองชัยภูมิ จังหวัดชัยภูมิ โครงการนิเทศนักศึกษาฝึกประสบการณ์วิชาชีพ หรือสหกิจศึกษา คณะศิลปศาสตร์และวิทยาศาสตร์ ประจำปีงบประมาณ 2569 กิจกรรมที่ 2 (ค่าน้ำมันเชื้อเพลิง) อาจารย์วราภรณ์ จันทร์เวียง | E15: 120 | F15: =F14-E15 -> 65356
A16: 3 ก.ย. 69 | B16: 454/69 | C16: ค่าใช้จ่ายเดินทางไปราชการ เพื่อนิเทศนักศึกษาสหกิจศึกษา หลักสูตรวิศวกรรมศาสตรบัณฑิต สาขาวิชาวิศวกรรมอุตสาหรการและโลจิสติกส์ ในวันที่ 18 - 20 สิงหาคม 2569 ในพื้นที่จังหวัดสมุทรปราการ และจังหวัดชลบุรีโครงการนิเทศนักศึกษาฝึกประสบการณ์วิชาชีพ หรือสหกิจศึกษา คณะศิลปศาสตร์และวิทยาศาสตร์ ประจำปีงบประมาณ 2569 กิจกรรมที่ 2 (ค่าน้ำมันเชื้อเพลิง/ค่าที่พัก/ค่าเบี้ยเลี้ยง) อาจารย์วราภรณ์ จันทร์เวียง | E16: 9704 | F16: =F15-E16 -> 55652
A17: 531/69 | B17: 15 ก.ย. 69 | C17: จัดซื้อวัสดุกิจกรรมที่ 1 จำนวน 3 รายการ จำนวน 160,000 บาท กิจกรรมที่ 2 จำนวน 3 รายการ จำนวน 52,000 บาท โครงการนิเทศนักศึกษาฝึกประสบการณ์วิชาชีพ หรือสหกิจศึกษา คณะศิลปศาสตร์และวิทยาศาสตร์ ประจำปีงบประมาณ 2569 (อัญชรี ยูทิลิตี้) อาจารย์ ดร.รัชวุธ สุทธิ | E17: 52000 | F17: =F16-E17 -> 3652
A18: รวมทั้งสิ้น | D18: =D4 -> 87760 | E18: =SUM(E4:E17) -> 84108 | F18: =D18-E18 -> 3652
C20: *หมายเหตุ

Sheet 8.โครงการรับประเมิน
A1: โครงการรับการตรวจประเมินคุณภาพการศึกษาภายใน คณะศิลปศาสตร์และวิทยาศาสตร์ ประจำปีการศึกษา 2568 | F1: หน้าหลัก
A2: ระยะเวลาดำเนินโครงการ ในไตรมาสที่ 3 - 4 ( เม.ย. - ก.ย. 69)
A3: รหัสโครงการ | B3: ชื่อโครงการ | C3: งบประมาณ | D3: เบิก-จ่าย | E3: คงเหลือ
B4: ยอดเงินทั้งหมด | C4: 130000 | E4: =C4-D4 -> 130000
A5: กิจกรรมที่ 8.1 | B5: กิจกรรมที่ 1 : ตรวจประเมินคุณภาพการศึกษาภายใน ระดับหลักสูตร | C5: ='กิจกรรมที่ 8.1'!D15 -> 108000 | D5: ='กิจกรรมที่ 8.1'!E15 -> 108000 | E5: =C5-D5 -> 0
A6: กิจกรรมที่ 8.2 | B6: กิจกรรมที่ 2 : ตรวจประเมินคุณภาพการศึกษาภายใน ระดับคณะ | C6: ='กิจกรรมที่ 8.2'!D7 -> 22000 | D6: ='กิจกรรมที่ 8.2'!E7 -> 14786 | E6: =C6-D6 -> 7214
A7: รวมทั้งสิ้น | C7: =SUM(C5:C6) -> 130000 | D7: =SUM(D5:D6) -> 122786 | E7: =C7-D7 -> 7214
A9: ผู้รับผิดชอบโครงการ

Sheet กิจกรรมที่ 8.1
A1: กิจกรรมที่ 1 : ตรวจประเมินคุณภาพการศึกษาภายใน ระดับหลักสูตร | G1: โครงการประเมิน
C2: ระยะเวลาดำเนินโครงการ ในไตรมาสที่ 3 - 4 ( เม.ย. - ก.ย. 69)
A3: ว/ด/ป/ | B3: ลำดับ | C3: รายการ | D3: รับ/อนุมัติ | E3: เบิก | F3: คงเหลือ
C4: กิจกรรมที่ 1 : ตรวจประเมินคุณภาพการศึกษาภายใน ระดับหลักสูตร | D4: 108000 | F4: =D4-E4 -> 108000
A5: 6 ก.ค. 69 | B5: 282/69 | C5: ค่าใช้จ่ายโครงการรับการตรวจประเมินคุณภาพการศึกษาภายใน คณะศิลปศาสตร์และวิทยาศาสตร์ ประจำปีการศึกษา 2568 ระดับหลักสูตร (หลักสูตรศิลปศาสตรมหาบัณฑิต สาขาวิชายุทธศาสตร์การพัฒนา) กิจกรรมที่ 1 ในวันที่ 13 มิถุนายน 2569 ณ อาคารปฏิบัติการเทคโนโลยีออุตสาหกรรม มหาวิทยาลัยราชภัฏชัยภูมิ (ค่าตอบแทนกรรมการ) รศ.ดร.สุนทร ปัญญะพงษ์ | E5: 6000 | F5: =F4+D5-E5 -> 102000
A6: 9 ก.ค. 69 | B6: 293/69 | C6: ค่าใช้จ่ายโครงการรับการตรวจประเมินคุณภาพการศึกษาภายใน คณะศิลปศาสตร์และวิทยาศาสตร์ ประจำปีการศึกษา 2568 ระดับหลักสูตร (หลักสูตรรัฐศาสตรมหาบัณฑิต สาขารัฐศาสตร์ และหลักสูตรรัฐศาสตรดุษฎีบัณฑิต สาขารัฐศาสตร์) กิจกรรมที่ 1 ในวันที่ 14 - 15 พฤษภาคม 2569 ณ อาคารปฏิบัติการเทคโนโลยีออุตสาหกรรม มหาวิทยาลัยราชภัฏชัยภูมิ (ค่าตอบแทนกรรมการ) นางสาวณัฐนรี ไทยภัดี | E6: 12000 | F6: =F5+D6-E6 -> 90000
A7: 21 ก.ค. 69 | B7: 322/69 | C7: ค่าใช้จ่ายโครงการรับการตรวจประเมินคุณภาพการศึกษาภายใน คณะศิลปศาสตร์และวิทยาศาสตร์ ประจำปีการศึกษา 2568 ระดับหลักสูตร (หลักสูตรรัฐศาสตรบัณฑิต สาขารัฐศาสตร์ และหลักสูตรรัฐประศาสนศาสตรบัณฑิต สาขารัฐประศาสนศาสตร์) กิจกรรมที่ 1 ในวันที่ 28 พฤษภาคม 2569 ณ อาคารปฏิบัติการเทคโนโลยีออุตสาหกรรม มหาวิทยาลัยราชภัฏชัยภูมิ (ค่าตอบแทนกรรมการ) ผศ.วิมลศิลป์ ปรุงชัยภูมิ | E7: 12000 | F7: =F6+D7-E7 -> 78000
A8: 3 ส.ค. 69 | B8: 329/69 | C8: ค่าใช้จ่ายโครงการรับการตรวจประเมินคุณภาพการศึกษาภายใน คณะศิลปศาสตร์และวิทยาศาสตร์ ประจำปีการศึกษา 2568 ระดับหลักสูตร จำนวน 1 หลักสูตร (สาขาวิชาวิศวกรรมการผลิตและระบบอัตโนมัติ ) กิจกรรมที่ 1 ในวันที่ 22 พฤษภาคม 2569 ณ อาคารปฏิบัติการเทคโนโลยีออุตสาหกรรม มหาวิทยาลัยราชภัฏชัยภูมิ (ค่าตอบแทนกรรมการ) นางสาวณัฐนรี ไทยภักดี | E8: 6000 | F8: =F7+D8-E8 -> 72000
A9: 4 ส.ค.69 | B9: 334/69 | C9: ค่าใช้จ่ายโครงการรับการตรวจประเมินคุณภาพการศึกษาภายใน คณะศิลปศาสตร์และวิทยาศาสตร์ ประจำปีการศึกษา 2568 ระดับหลักสูตร จำนวน 1 หลักสูตร (หลักสูตรบริหารธุรกิจดุษฎีบัณฑิต สาขาวิชาการจัดการธุรกิจและนวัตกรรม ) กิจกรรมที่ 1 ในวันที่ 2 กรกฎาคม 2569 ณ อาคารปฏิบัติการเทคโนโลยีออุตสาหกรรม มหาวิทยาลัยราชภัฏชัยภูมิ (ค่าตอบแทนกรรมการ) ผศ.ดร.อัญชลี ชัยศรี | E9: 6000 | F9: =F8+D9-E9 -> 66000
A10: 6 ส.ค. 69 | B10: 338/69 | C10: ค่าใช้จ่ายโครงการรับการตรวจประเมินคุณภาพการศึกษาภายใน คณะศิลปศาสตร์และวิทยาศาสตร์ ประจำปีการศึกษา 2568 ระดับหลักสูตร จำนวน 2 หลักสูตร (หลักสูตรบริหารธุรกิจบัณฑิต สาขาบริหารธุรกิจ และสาขาการเป็นผู้ประกอบการสตาร์ทอัพด้านการท่องเที่ยวและโรงแรม ) กิจกรรมที่ 1 ในวันที่ 22 พฤษภาคม 2569 ณ อาคารปฏิบัติการเทคโนโลยีออุตสาหกรรม มหาวิทยาลัยราชภัฏชัยภูมิ (ค่าตอบแทนกรรมการ) ผศ.ดร.อารีรัตน์ พัฒนชีวะพลู | E10: 12000 | F10: =F9+D10-E10 -> 54000
A11: 6 ส.ค. 69 | B11: 339/69 | C11: ค่าใช้จ่ายโครงการรับการตรวจประเมินคุณภาพการศึกษาภายใน คณะศิลปศาสตร์และวิทยาศาสตร์ ประจำปีการศึกษา 2568 ระดับหลักสูตร จำนวน 2 หลักสูตร (หลักสูตรนิติศาสตรบัณฑิต สาขาวิชานิติศาสตร์ และหลักสูตรรัฐประศาสนศาสตรบัณฑิต สาขาวิชารัฐประศาสนศาสตร์) กิจกรรมที่ 1 ในวันที่ 29 พฤษภาคม 2569 ณ อาคารปฏิบัติการเทคโนโลยีออุตสาหกรรม มหาวิทยาลัยราชภัฏชัยภูมิ (ค่าตอบแทนกรรมการ) ผศ.วิมลศิลป์ ปรุงชัยภูมิ | E11: 12000 | F11: =F10+D11-E11 -> 42000
A12: 10 ส.ค. 69 | B12: 343/69 | C12: ค่าใช้จ่ายโครงการรับการตรวจประเมินคุณภาพการศึกษาภายใน คณะศิลปศาสตร์และวิทยาศาสตร์ ประจำปีการศึกษา 2568 ระดับหลักสูตร จำนวน 1 หลักสูตร (หลักสูตรศิลปกรรมศาสตรบัณฑิต สาขาวิชาศิลปะและนวัตกรรมการออกแบบ) กิจกรรมที่ 1 ในวันที่ 29 พฤษภาคม 2569 ณ อาคารปฏิบัติการเทคโนโลยีออุตสาหกรรม มหาวิทยาลัยราชภัฏชัยภูมิ (ค่าตอบแทนกรรมการ) ผศ.วิมลศิลป์ ปรุงชัยภูมิ | E12: 6000 | F12: =F11+D12-E12 -> 36000
A13: 13 ส.ค. 69 | B13: 348/69 | C13: ค่าใช้จ่ายโครงการรับการตรวจประเมินคุณภาพการศึกษาภายใน คณะศิลปศาสตร์และวิทยาศาสตร์ ประจำปีการศึกษา 2568 ระดับหลักสูตร จำนวน 4 หลักสูตร (วิศวกรรมเครื่องกล/วิศวกรรมุตสาหการและโลจิสติกส์/สาธารณสุขศาสตร์/วิทยาการคอมพิวเตอร์) กิจกรรมที่ 1 ในวันที่ 18 - 21 พฤษภาคม 2569 ณ อาคารปฏิบัติการเทคโนโลยีออุตสาหกรรม มหาวิทยาลัยราชภัฏชัยภูมิ (ค่าตอบแทนกรรมการ) น.ส.ณัฐนรี ไทยภักดี | E13: 24000 | F13: =F12+D13-E13 -> 12000
A14: 19 ส.ค. 69 | B14: 365/69 | C14: ค่าใช้จ่ายโครงการรับการตรวจประเมินคุณภาพการศึกษาภายใน คณะศิลปศาสตร์และวิทยาศาสตร์ ประจำปีการศึกษา 2568 ระดับหลักสูตร จำนวน 2 หลักสูตร (หลักสูตรบริหารธุรกิจมหาบัณฑิต สาขาการจัดการธุรกิจและนวัตกรรม และหลักสูตรศิลปศาสตรบัณฑิต สาขาสหวิทยาการเพื่อการพัฒนาท้องถิ่น) กิจกรรมที่ 1 ในวันที่ 25 พฤษภาคม 2569 ณ อาคารปฏิบัติการเทคโนโลยีออุตสาหกรรม มหาวิทยาลัยราชภัฏชัยภูมิ (ค่าตอบแทนกรรมการ) ผศ.ดร.อารีรัตน์ พัฒนชีวะพลู | E14: 12000
A15: รวมทั้งสิ้น | D15: =SUM(D4:D5) -> 108000 | E15: =SUM(E5:E14) -> 108000 | F15: =D15-E15 -> 0
C17: *หมายเหตุ

Sheet กิจกรรมที่ 8.2
A1: กิจกรรมที่ 2 ตรวจประเมินคุณภาพการศึกษาภายใน ระดับคณะ | G1: โครงการประเมิน
C2: ระยะเวลาดำเนินโครงการ ในไตรมาสที่ 4 ( ก.ค. - ก.ย. 69)
A3: ว/ด/ป/ | B3: ลำดับ | C3: รายการ | D3: รับ/อนุมัติ | E3: เบิก | F3: คงเหลือ
C4: กิจกรรมที่ 2 ตรวจประเมินคุณภาพการศึกษาภายใน ระดับคณะ | D4: 22000 | F4: =D4-E4 -> 22000
A5: 3 ก.ย. 69 | B5: 455/69 | C5: ค่าใช้จ่ายโครงการรับการตรวจประเมินคุณภาพการศึกษาภายใน คณะศิลปศาสตร์และวิทยาศาสตร์ ประจำปีการศึกษา 2568กิจกรรมที่ 2 วันที่ 14 สิงหาคม 2569 ณ ห้อง Smart Classroom ชั้น 1 อาคารคณะศิลปศาสตร์และวิทยาศาสตร์ (ค่าตอบแทนวิทยากร) อาจารย์ ดร.สิริพร ขันทองคำ | E5: 3600 | F5: =F4+D5-E5 -> 18400
A6: 15 ก.ย. 69 | B6: 529/69 | C6: ค่าใช้จ่ายโครงการรับการตรวจประเมินคุณภาพการศึกษาภายใน คณะศิลปศาสตร์และวิทยาศาสตร์ ประจำปีการศึกษา 2568 วันที่ 14 กันยายน 2569 ณ ห้อง Smart classroom ชั้น 1 คณะศิลปศาสตร์และวิทยาศาสตร์ (ค่าตอบแทนวิทยากร/ค่าอาหารว่าง/ค่าอาหารกลางวัน/ค่าน้ำมันเชื้อเพลิง) นางมาลินี วาสสามัคคี | E6: 11186 | F6: =F5+D6-E6 -> 7214
A7: รวมทั้งสิ้น | D7: =SUM(D4:D5) -> 22000 | E7: =SUM(E4:E6) -> 14786 | F7: =D7-E7 -> 7214
C9: *หมายเหตุ

Sheet 9.โครงการสู่ความเป็นเลิศ
A1: โครงการบริหารจัดการคณะสู่ความเป็นเลิศ คณะศิลปศาสตร์และวิทยาศาสตร์ | G1: หน้าหลัก
A2: ระยะเวลาดำเนินโครงการ ไตรมาสที่ 1 - 4 ( ต.ค.68 - ก.ย. 69)
A3: ว/ด/ป/ | B3: ลำดับ | C3: รายการ | D3: งบจัดสรร | E3: เบิก | F3: คงเหลือ
C4: กิจกรรมที่ 2 : การประชุมคณะกรรมการประจำหน่วยงาน | D4: 120600 | F4: =D4-E4 -> 120600
A5: 21 พ.ย. 68 | B5: 001/68 | C5: ค่าใช้จ่ายในการประชุมคณะกรรมการประจำคณะ ครั้งที่ 10/2568 ในวันที่ 14 พฤศจิกายน 2568 ณ ห้องประชุม 2 ชั้น 1 อาคารปฏิบัติการเทคโนโลยีอุตสาหกรรม โครงการบริหารจัดการคณะสู่ความเป็นเลิศฯ กิจกรรมที่ 2 (ค่าเบี้ยประชุม) นางมาลินี วาสสามัคคี | E5: 11800 | F5: =F4+D5-E5 -> 108800
A6: 2 ธ.ค. 68 | B6: 008/69 | C6: ค่าใช้จ่ายในการประชุมคณะกรรมการประจำคณะ ครั้งที่ 9/2568 ในวันที่ 22 ตุลาคม 2568 ผ่านสื่อออนไลน์ โครงการบริหารจัดการคณะสู่ความเป็นเลิศฯ กิจกรรมที่ 2 (ค่าเบี้ยประชุม) นางมาลินี วาสสามัคคี | E6: 12300 | F6: =F5+D6-E6 -> 96500
A7: 5 ม.ค.69 | B7: 022/69 | C7: ค่าใช้จ่ายในการประชุมคณะกรรมการประจำคณะ ครั้งที่ 11/2568 ในวันที่ 24 ธันวาคม 2568 โครงการบริหารจัดการคณะสู่ความเป็นเลิศฯ กิจกรรมที่ 2 (ค่าอาหารว่าง) นางมาลินี วาสสามัคคี | E7: 12800 | F7: =F6+D7-E7 -> 83700
A8: 20 ม.ค.69 | B8: 039/69 | C8: ค่าใช้จ่ายในการประชุมคณะกรรมการประจำคณะ ครั้งที่ 1/2569 ในวันที่ 13 มกราคม 2569 โครงการบริหารจัดการคณะสู่ความเป็นเลิศฯ กิจกรรมที่ 2 (ค่าเบี้ยประชุมคณะกรรมการ) นางมาลินี วาสสามัคคี | E8: 12800 | F8: =F7+D8-E8 -> 70900
